Workbook

Sheet 사용방법
B1: 성분분석기 정밀도·정확도 검증 양식
B3: ■ 시트 구성
B4: 1. 기준SD : 제조사 정밀도 표(1×SD)를 '베이스 / 원소 / 농도레벨 / SD' 한 줄씩 입력한 Back data (판정 기준값)
B5: 2. 원소정보 : 원소별 UV Probe 여부, 검출한계(ppm), 검량범위 상한(%)
B6: 3. 기준표_확인 : 기준SD 데이터를 제조사 원본 표 모양으로 다시 펼친 화면 → 종이 원본과 나란히 놓고 오타 확인용
B7: 4. 검증 : 측정값 10회를 입력하면 평균·SD·RSD, 제조사 기준SD(보간), 정밀도/정확도 판정이 자동 계산
B9: ■ 셀 색상 규칙
B10: 노란 배경 + 파란 글씨 = 직접 입력하는 칸 / 회색 배경 + 검은 글씨 = 수식(수정 금지)
B12: ■ 사용 순서
B13: ① '기준표_확인' 시트를 제조사 원본 표와 비교해 입력 오류가 없는지 먼저 확인합니다.
B14: ② '검증' 시트에서 베이스(Fe/Cu/Al), 시편번호, 원소, 인증값, (있으면) 인증불확도를 입력합니다.
B15: ③ 같은 시편을 연속 10회 측정한 값을 '측정1~10' 칸에 입력합니다 (최소 2회부터 계산).
... B37: 출처: SPECTRO Application Report, 6. Typical Detection Limits and Precision Fe-Base (제조사 제공)

Sheet 검증
A1: 판정 설정
A2: 정밀도 판정계수 | C2: 1 | D2: 합격: 측정 SD ≤ 기준SD × 판정계수 (제조사 값은 Typical 값 - 사내 기준에 맞게 1.0~2.0)
A3: 정확도 허용 배수 | C3: 2 | D3: 인증불확도 미입력 시 허용편차 = 기준SD × 이 배수
A5: 베이스 | B5: 시편번호 | C5: 원소 | D5: 인증값(%) | E5: 인증불확도(%) | F5: 측정1 | G5: 측정2 | H5: 측정3 | I5: 측정4 | J5: 측정5 | K5: 측정6 | L5: 측정7 | M5: 측정8 | N5: 측정9 | O5: 측정10 | P5: 측정횟수 | Q5: 평균(%) | R5: SD(%) | S5: RSD(%) | T5: 기준SD(%) (보간) | U5: SD비 측정/기준 | V5: 정밀도 판정 | W5: 편차(%) 평균-인증 | X5: 허용편차(%) | Y5: 정확도 판정 | Z5: 비고 | AA5: 키 | AB5: 하한레벨 | AC5: 상한레벨 | AD5: 하한SD | AE5: 상한SD
A6: Fe | B6: 예시(삭제 후 사용) | C6: Mn | D6: 0.85 | E6: 0.01 | F6: 0.852 | G6: 0.848 | H6: 0.855 | I6: 0.85 | J6: 0.847 | K6: 0.853 | L6: 0.849 | M6: 0.851 | N6: 0.854 | O6: 0.846 | P6: =COUNT(F6:O6) -> 10 | Q6: =IF(P6<2,"",AVERAGE(F6:O6)) -> 0.8505 | R6: =IF(P6<2,"",STDEV(F6:O6)) -> 0.0030276504 | S6: =IF(P6<2,"",IF(Q6=0,"",R6/Q6*100)) -> 0.35598476 | T6: =IF(AB6="","",IF(AB6=AC6,AD6,AD6+(AE6-AD6)*(Q6-AB6)/(AC6-AB6))) -> 0.010206 | U6: =IF(OR(T6="",R6=""),"",IF(T6=0,"",R6/T6)) -> 0.29665396 | V6: =IF(Q6="","",IF(T6="","기준없음",IF(R6<=T6*$C$2,"합격","불합격"))) -> 합격 | W6: =IF(OR(Q6="",D6=""),"",Q6-D6) -> 0.0005 | X6: =IF(W6="","",IF(E6<>"",E6,IF(T6="","",T6*$C$3))) -> 0.01 | Y6: =IF(OR(W6="",X6=""),"",IF(ABS(W6)<=X6,"합격","불합격")) -> 합격 | Z6: =IF(OR(AA6="",Q6=""),"",IF(AB6="","기준SD 데이터 없음 ",IF(Q6<_xlfn.MINIFS(기준SD!$C$2:$C$500,기준SD!$E$2:$E$500,AA6),"최저 레벨 미만→최저 레벨 SD 적용 ",IF(Q6>_xlfn.MAXIFS(기준SD!$C$2:$C$500,기준SD!$E$2:$E$500,AA6),"최고 레벨 초과→최고 레벨 SD 적용 ","")))&IF(SUMIFS(원소정보!$E$2:$E$200,원소정보!$F$2:$F$200,AA6)>0,IF(Q6>SUMIFS(원소정보!$E$2:$E$200,원소정보!$F$2:$F$200,AA6),"검량범위 초과 ",""),"")&IF(SUMIFS(원소정보!$D$2:$D$200,원소정보!$F$2:$F$200,AA6)>0,IF(Q6<SUMIFS(원소정보!$D$2:$D$200,원소정보!$F$2:$F$200,AA6)/10000,"검출한계 미만",""),"")) | AA6: =IF(OR(A6="",C6=""),"",A6&"|"&C6) -> Fe|Mn | AB6: =IF(OR(AA6="",Q6=""),"",IF(COUNTIF(기준SD!$E$2:$E$500,AA6)=0,"",IF(COUNTIFS(기준SD!$E$2:$E$500,AA6,기준SD!$C$2:$C$500,"<="&Q6)=0,_xlfn.MINIFS(기준SD!$C$2:$C$500,기준SD!$E$2:$E$500,AA6),_xlfn.MAXIFS(기준SD!$C$2:$C$500,기준SD!$E$2:$E$500,AA6,기준SD!$C$2:$C$500,"<="&Q6)))) -> 0.5 | AC6: =IF(AB6="","",IF(COUNTIFS(기준SD!$E$2:$E$500,AA6,기준SD!$C$2:$C$500,">="&Q6)=0,_xlfn.MAXIFS(기준SD!$C$2:$C$500,기준SD!$E$2:$E$500,AA6),_xlfn.MINIFS(기준SD!$C$2:$C$500,기준SD!$E$2:$E$500,AA6,기준SD!$C$2:$C$500,">="&Q6))) -> 1 | AD6: =IF(AB6="","",SUMIFS(기준SD!$D$2:$D$500,기준SD!$E$2:$E$500,AA6,기준SD!$C$2:$C$500,AB6)) -> 0.006 | AE6: =IF(AC6="","",SUMIFS(기준SD!$D$2:$D$500,기준SD!$E$2:$E$500,AA6,기준SD!$C$2:$C$500,AC6)) -> 0.012
A7: Fe | C7: Al | P7: =COUNT(F7:O7) -> 0 | Q7: =IF(P7<2,"",AVERAGE(F7:O7)) | R7: =IF(P7<2,"",STDEV(F7:O7)) | S7: =IF(P7<2,"",IF(Q7=0,"",R7/Q7*100)) | T7: =IF(AB7="","",IF(AB7=AC7,AD7,AD7+(AE7-AD7)*(Q7-AB7)/(AC7-AB7))) | U7: =IF(OR(T7="",R7=""),"",IF(T7=0,"",R7/T7)) | V7: =IF(Q7="","",IF(T7="","기준없음",IF(R7<=T7*$C$2,"합격","불합격"))) | W7: =IF(OR(Q7="",D7=""),"",Q7-D7) | X7: =IF(W7="","",IF(E7<>"",E7,IF(T7="","",T7*$C$3))) | Y7: =IF(OR(W7="",X7=""),"",IF(ABS(W7)<=X7,"합격","불합격")) | Z7: =IF(OR(AA7="",Q7=""),"",IF(AB7="","기준SD 데이터 없음 ",IF(Q7<_xlfn.MINIFS(기준SD!$C$2:$C$500,기준SD!$E$2:$E$500,AA7),"최저 레벨 미만→최저 레벨 SD 적용 ",IF(Q7>_xlfn.MAXIFS(기준SD!$C$2:$C$500,기준SD!$E$2:$E$500,AA7),"최고 레벨 초과→최고 레벨 SD 적용 ","")))&IF(SUMIFS(원소정보!$E$2:$E$200,원소정보!$F$2:$F$200,AA7)>0,IF(Q7>SUMIFS(원소정보!$E$2:$E$200,원소정보!$F$2:$F$200,AA7),"검량범위 초과 ",""),"")&IF(SUMIFS(원소정보!$D$2:$D$200,원소정보!$F$2:$F$200,AA7)>0,IF(Q7<SUMIFS(원소정보!$D$2:$D$200,원소정보!$F$2:$F$200,AA7)/10000,"검출한계 미만",""),"")) | AA7: =IF(OR(A7="",C7=""),"",A7&"|"&C7) -> Fe|Al | AB7: =IF(OR(AA7="",Q7=""),"",IF(COUNTIF(기준SD!$E$2:$E$500,AA7)=0,"",IF(COUNTIFS(기준SD!$E$2:$E$500,AA7,기준SD!$C$2:$C$500,"<="&Q7)=0,_xlfn.MINIFS(기준SD!$C$2:$C$500,기준SD!$E$2:$E$500,AA7),_xlfn.MAXIFS(기준SD!$C$2:$C$500,기준SD!$E$2:$E$500,AA7,기준SD!$C$2:$C$500,"<="&Q7)))) | AC7: =IF(AB7="","",IF(COUNTIFS(기준SD!$E$2:$E$500,AA7,기준SD!$C$2:$C$500,">="&Q7)=0,_xlfn.MAXIFS(기준SD!$C$2:$C$500,기준SD!$E$2:$E$500,AA7),_xlfn.MINIFS(기준SD!$C$2:$C$500,기준SD!$E$2:$E$500,AA7,기준SD!$C$2:$C$500,">="&Q7))) | AD7: =IF(AB7="","",SUMIFS(기준SD!$D$2:$D$500,기준SD!$E$2:$E$500,AA7,기준SD!$C$2:$C$500,AB7)) | AE7: =IF(AC7="","",SUMIFS(기준SD!$D$2:$D$500,기준SD!$E$2:$E$500,AA7,기준SD!$C$2:$C$500,AC7))
A8: Fe | C8: As | P8: =COUNT(F8:O8) -> 0 | Q8: =IF(P8<2,"",AVERAGE(F8:O8)) | R8: =IF(P8<2,"",STDEV(F8:O8)) | S8: =IF(P8<2,"",IF(Q8=0,"",R8/Q8*100)) | T8: =IF(AB8="","",IF(AB8=AC8,AD8,AD8+(AE8-AD8)*(Q8-AB8)/(AC8-AB8))) | U8: =IF(OR(T8="",R8=""),"",IF(T8=0,"",R8/T8)) | V8: =IF(Q8="","",IF(T8="","기준없음",IF(R8<=T8*$C$2,"합격","불합격"))) | W8: =IF(OR(Q8="",D8=""),"",Q8-D8) | X8: =IF(W8="","",IF(E8<>"",E8,IF(T8="","",T8*$C$3))) | Y8: =IF(OR(W8="",X8=""),"",IF(ABS(W8)<=X8,"합격","불합격")) | Z8: =IF(OR(AA8="",Q8=""),"",IF(AB8="","기준SD 데이터 없음 ",IF(Q8<_xlfn.MINIFS(기준SD!$C$2:$C$500,기준SD!$E$2:$E$500,AA8),"최저 레벨 미만→최저 레벨 SD 적용 ",IF(Q8>_xlfn.MAXIFS(기준SD!$C$2:$C$500,기준SD!$E$2:$E$500,AA8),"최고 레벨 초과→최고 레벨 SD 적용 ","")))&IF(SUMIFS(원소정보!$E$2:$E$200,원소정보!$F$2:$F$200,AA8)>0,IF(Q8>SUMIFS(원소정보!$E$2:$E$200,원소정보!$F$2:$F$200,AA8),"검량범위 초과 ",""),"")&IF(SUMIFS(원소정보!$D$2:$D$200,원소정보!$F$2:$F$200,AA8)>0,IF(Q8<SUMIFS(원소정보!$D$2:$D$200,원소정보!$F$2:$F$200,AA8)/10000,"검출한계 미만",""),"")) | AA8: =IF(OR(A8="",C8=""),"",A8&"|"&C8) -> Fe|As | AB8: =IF(OR(AA8="",Q8=""),"",IF(COUNTIF(기준SD!$E$2:$E$500,AA8)=0,"",IF(COUNTIFS(기준SD!$E$2:$E$500,AA8,기준SD!$C$2:$C$500,"<="&Q8)=0,_xlfn.MINIFS(기준SD!$C$2:$C$500,기준SD!$E$2:$E$500,AA8),_xlfn.MAXIFS(기준SD!$C$2:$C$500,기준SD!$E$2:$E$500,AA8,기준SD!$C$2:$C$500,"<="&Q8)))) | AC8: =IF(AB8="","",IF(COUNTIFS(기준SD!$E$2:$E$500,AA8,기준SD!$C$2:$C$500,">="&Q8)=0,_xlfn.MAXIFS(기준SD!$C$2:$C$500,기준SD!$E$2:$E$500,AA8),_xlfn.MINIFS(기준SD!$C$2:$C$500,기준SD!$E$2:$E$500,AA8,기준SD!$C$2:$C$500,">="&Q8))) | AD8: =IF(AB8="","",SUMIFS(기준SD!$D$2:$D$500,기준SD!$E$2:$E$500,AA8,기준SD!$C$2:$C$500,AB8)) | AE8: =IF(AC8="","",SUMIFS(기준SD!$D$2:$D$500,기준SD!$E$2:$E$500,AA8,기준SD!$C$2:$C$500,AC8))
A9: Fe | C9: B | P9: =COUNT(F9:O9) -> 0 | Q9: =IF(P9<2,"",AVERAGE(F9:O9)) | R9: =IF(P9<2,"",STDEV(F9:O9)) | S9: =IF(P9<2,"",IF(Q9=0,"",R9/Q9*100)) | T9: =IF(AB9="","",IF(AB9=AC9,AD9,AD9+(AE9-AD9)*(Q9-AB9)/(AC9-AB9))) | U9: =IF(OR(T9="",R9=""),"",IF(T9=0,"",R9/T9)) | V9: =IF(Q9="","",IF(T9="","기준없음",IF(R9<=T9*$C$2,"합격","불합격"))) | W9: =IF(OR(Q9="",D9=""),"",Q9-D9) | X9: =IF(W9="","",IF(E9<>"",E9,IF(T9="","",T9*$C$3))) | Y9: =IF(OR(W9="",X9=""),"",IF(ABS(W9)<=X9,"합격","불합격")) | Z9: =IF(OR(AA9="",Q9=""),"",IF(AB9="","기준SD 데이터 없음 ",IF(Q9<_xlfn.MINIFS(기준SD!$C$2:$C$500,기준SD!$E$2:$E$500,AA9),"최저 레벨 미만→최저 레벨 SD 적용 ",IF(Q9>_xlfn.MAXIFS(기준SD!$C$2:$C$500,기준SD!$E$2:$E$500,AA9),"최고 레벨 초과→최고 레벨 SD 적용 ","")))&IF(SUMIFS(원소정보!$E$2:$E$200,원소정보!$F$2:$F$200,AA9)>0,IF(Q9>SUMIFS(원소정보!$E$2:$E$200,원소정보!$F$2:$F$200,AA9),"검량범위 초과 ",""),"")&IF(SUMIFS(원소정보!$D$2:$D$200,원소정보!$F$2:$F$200,AA9)>0,IF(Q9<SUMIFS(원소정보!$D$2:$D$200,원소정보!$F$2:$F$200,AA9)/10000,"검출한계 미만",""),"")) | AA9: =IF(OR(A9="",C9=""),"",A9&"|"&C9) -> Fe|B | AB9: =IF(OR(AA9="",Q9=""),"",IF(COUNTIF(기준SD!$E$2:$E$500,AA9)=0,"",IF(COUNTIFS(기준SD!$E$2:$E$500,AA9,기준SD!$C$2:$C$500,"<="&Q9)=0,_xlfn.MINIFS(기준SD!$C$2:$C$500,기준SD!$E$2:$E$500,AA9),_xlfn.MAXIFS(기준SD!$C$2:$C$500,기준SD!$E$2:$E$500,AA9,기준SD!$C$2:$C$500,"<="&Q9)))) | AC9: =IF(AB9="","",IF(COUNTIFS(기준SD!$E$2:$E$500,AA9,기준SD!$C$2:$C$500,">="&Q9)=0,_xlfn.MAXIFS(기준SD!$C$2:$C$500,기준SD!$E$2:$E$500,AA9),_xlfn.MINIFS(기준SD!$C$2:$C$500,기준SD!$E$2:$E$500,AA9,기준SD!$C$2:$C$500,">="&Q9))) | AD9: =IF(AB9="","",SUMIFS(기준SD!$D$2:$D$500,기준SD!$E$2:$E$500,AA9,기준SD!$C$2:$C$500,AB9)) | AE9: =IF(AC9="","",SUMIFS(기준SD!$D$2:$D$500,기준SD!$E$2:$E$500,AA9,기준SD!$C$2:$C$500,AC9))
A10: Fe | C10: C | P10: =COUNT(F10:O10) -> 0 | Q10: =IF(P10<2,"",AVERAGE(F10:O10)) | R10: =IF(P10<2,"",STDEV(F10:O10)) | S10: =IF(P10<2,"",IF(Q10=0,"",R10/Q10*100)) | T10: =IF(AB10="","",IF(AB10=AC10,AD10,AD10+(AE10-AD10)*(Q10-AB10)/(AC10-AB10))) | U10: =IF(OR(T10="",R10=""),"",IF(T10=0,"",R10/T10)) | V10: =IF(Q10="","",IF(T10="","기준없음",IF(R10<=T10*$C$2,"합격","불합격"))) | W10: =IF(OR(Q10="",D10=""),"",Q10-D10) | X10: =IF(W10="","",IF(E10<>"",E10,IF(T10="","",T10*$C$3))) | Y10: =IF(OR(W10="",X10=""),"",IF(ABS(W10)<=X10,"합격","불합격")) | Z10: =IF(OR(AA10="",Q10=""),"",IF(AB10="","기준SD 데이터 없음 ",IF(Q10<_xlfn.MINIFS(기준SD!$C$2:$C$500,기준SD!$E$2:$E$500,AA10),"최저 레벨 미만→최저 레벨 SD 적용 ",IF(Q10>_xlfn.MAXIFS(기준SD!$C$2:$C$500,기준SD!$E$2:$E$500,AA10),"최고 레벨 초과→최고 레벨 SD 적용 ","")))&IF(SUMIFS(원소정보!$E$2:$E$200,원소정보!$F$2:$F$200,AA10)>0,IF(Q10>SUMIFS(원소정보!$E$2:$E$200,원소정보!$F$2:$F$200,AA10),"검량범위 초과 ",""),"")&IF(SUMIFS(원소정보!$D$2:$D$200,원소정보!$F$2:$F$200,AA10)>0,IF(Q10<SUMIFS(원소정보!$D$2:$D$200,원소정보!$F$2:$F$200,AA10)/10000,"검출한계 미만",""),"")) | AA10: =IF(OR(A10="",C10=""),"",A10&"|"&C10) -> Fe|C | AB10: =IF(OR(AA10="",Q10=""),"",IF(COUNTIF(기준SD!$E$2:$E$500,AA10)=0,"",IF(COUNTIFS(기준SD!$E$2:$E$500,AA10,기준SD!$C$2:$C$500,"<="&Q10)=0,_xlfn.MINIFS(기준SD!$C$2:$C$500,기준SD!$E$2:$E$500,AA10),_xlfn.MAXIFS(기준SD!$C$2:$C$500,기준SD!$E$2:$E$500,AA10,기준SD!$C$2:$C$500,"<="&Q10)))) | AC10: =IF(AB10="","",IF(COUNTIFS(기준SD!$E$2:$E$500,AA10,기준SD!$C$2:$C$500,">="&Q10)=0,_xlfn.MAXIFS(기준SD!$C$2:$C$500,기준SD!$E$2:$E$500,AA10),_xlfn.MINIFS(기준SD!$C$2:$C$500,기준SD!$E$2:$E$500,AA10,기준SD!$C$2:$C$500,">="&Q10))) | AD10: =IF(AB10="","",SUMIFS(기준SD!$D$2:$D$500,기준SD!$E$2:$E$500,AA10,기준SD!$C$2:$C$500,AB10)) | AE10: =IF(AC10="","",SUMIFS(기준SD!$D$2:$D$500,기준SD!$E$2:$E$500,AA10,기준SD!$C$2:$C$500,AC10))
A11: Fe | C11: C(air) | P11: =COUNT(F11:O11) -> 0 | Q11: =IF(P11<2,"",AVERAGE(F11:O11)) | R11: =IF(P11<2,"",STDEV(F11:O11)) | S11: =IF(P11<2,"",IF(Q11=0,"",R11/Q11*100)) | T11: =IF(AB11="","",IF(AB11=AC11,AD11,AD11+(AE11-AD11)*(Q11-AB11)/(AC11-AB11))) | U11: =IF(OR(T11="",R11=""),"",IF(T11=0,"",R11/T11)) | V11: =IF(Q11="","",IF(T11="","기준없음",IF(R11<=T11*$C$2,"합격","불합격"))) | W11: =IF(OR(Q11="",D11=""),"",Q11-D11) | X11: =IF(W11="","",IF(E11<>"",E11,IF(T11="","",T11*$C$3))) | Y11: =IF(OR(W11="",X11=""),"",IF(ABS(W11)<=X11,"합격","불합격")) | Z11: =IF(OR(AA11="",Q11=""),"",IF(AB11="","기준SD 데이터 없음 ",IF(Q11<_xlfn.MINIFS(기준SD!$C$2:$C$500,기준SD!$E$2:$E$500,AA11),"최저 레벨 미만→최저 레벨 SD 적용 ",IF(Q11>_xlfn.MAXIFS(기준SD!$C$2:$C$500,기준SD!$E$2:$E$500,AA11),"최고 레벨 초과→최고 레벨 SD 적용 ","")))&IF(SUMIFS(원소정보!$E$2:$E$200,원소정보!$F$2:$F$200,AA11)>0,IF(Q11>SUMIFS(원소정보!$E$2:$E$200,원소정보!$F$2:$F$200,AA11),"검량범위 초과 ",""),"")&IF(SUMIFS(원소정보!$D$2:$D$200,원소정보!$F$2:$F$200,AA11)>0,IF(Q11<SUMIFS(원소정보!$D$2:$D$200,원소정보!$F$2:$F$200,AA11)/10000,"검출한계 미만",""),"")) | AA11: =IF(OR(A11="",C11=""),"",A11&"|"&C11) -> Fe|C(air) | AB11: =IF(OR(AA11="",Q11=""),"",IF(COUNTIF(기준SD!$E$2:$E$500,AA11)=0,"",IF(COUNTIFS(기준SD!$E$2:$E$500,AA11,기준SD!$C$2:$C$500,"<="&Q11)=0,_xlfn.MINIFS(기준SD!$C$2:$C$500,기준SD!$E$2:$E$500,AA11),_xlfn.MAXIFS(기준SD!$C$2:$C$500,기준SD!$E$2:$E$500,AA11,기준SD!$C$2:$C$500,"<="&Q11)))) | AC11: =IF(AB11="","",IF(COUNTIFS(기준SD!$E$2:$E$500,AA11,기준SD!$C$2:$C$500,">="&Q11)=0,_xlfn.MAXIFS(기준SD!$C$2:$C$500,기준SD!$E$2:$E$500,AA11),_xlfn.MINIFS(기준SD!$C$2:$C$500,기준SD!$E$2:$E$500,AA11,기준SD!$C$2:$C$500,">="&Q11))) | AD11: =IF(AB11="","",SUMIFS(기준SD!$D$2:$D$500,기준SD!$E$2:$E$500,AA11,기준SD!$C$2:$C$500,AB11)) | AE11: =IF(AC11="","",SUMIFS(기준SD!$D$2:$D$500,기준SD!$E$2:$E$500,AA11,기준SD!$C$2:$C$500,AC11))
A12: Fe | C12: Co | P12: =COUNT(F12:O12) -> 0 | Q12: =IF(P12<2,"",AVERAGE(F12:O12)) | R12: =IF(P12<2,"",STDEV(F12:O12)) | S12: =IF(P12<2,"",IF(Q12=0,"",R12/Q12*100)) | T12: =IF(AB12="","",IF(AB12=AC12,AD12,AD12+(AE12-AD12)*(Q12-AB12)/(AC12-AB12))) | U12: =IF(OR(T12="",R12=""),"",IF(T12=0,"",R12/T12)) | V12: =IF(Q12="","",IF(T12="","기준없음",IF(R12<=T12*$C$2,"합격","불합격"))) | W12: =IF(OR(Q12="",D12=""),"",Q12-D12) | X12: =IF(W12="","",IF(E12<>"",E12,IF(T12="","",T12*$C$3))) | Y12: =IF(OR(W12="",X12=""),"",IF(ABS(W12)<=X12,"합격","불합격")) | Z12: =IF(OR(AA12="",Q12=""),"",IF(AB12="","기준SD 데이터 없음 ",IF(Q12<_xlfn.MINIFS(기준SD!$C$2:$C$500,기준SD!$E$2:$E$500,AA12),"최저 레벨 미만→최저 레벨 SD 적용 ",IF(Q12>_xlfn.MAXIFS(기준SD!$C$2:$C$500,기준SD!$E$2:$E$500,AA12),"최고 레벨 초과→최고 레벨 SD 적용 ","")))&IF(SUMIFS(원소정보!$E$2:$E$200,원소정보!$F$2:$F$200,AA12)>0,IF(Q12>SUMIFS(원소정보!$E$2:$E$200,원소정보!$F$2:$F$200,AA12),"검량범위 초과 ",""),"")&IF(SUMIFS(원소정보!$D$2:$D$200,원소정보!$F$2:$F$200,AA12)>0,IF(Q12<SUMIFS(원소정보!$D$2:$D$200,원소정보!$F$2:$F$200,AA12)/10000,"검출한계 미만",""),"")) | AA12: =IF(OR(A12="",C12=""),"",A12&"|"&C12) -> Fe|Co | AB12: =IF(OR(AA12="",Q12=""),"",IF(COUNTIF(기준SD!$E$2:$E$500,AA12)=0,"",IF(COUNTIFS(기준SD!$E$2:$E$500,AA12,기준SD!$C$2:$C$500,"<="&Q12)=0,_xlfn.MINIFS(기준SD!$C$2:$C$500,기준SD!$E$2:$E$500,AA12),_xlfn.MAXIFS(기준SD!$C$2:$C$500,기준SD!$E$2:$E$500,AA12,기준SD!$C$2:$C$500,"<="&Q12)))) | AC12: =IF(AB12="","",IF(COUNTIFS(기준SD!$E$2:$E$500,AA12,기준SD!$C$2:$C$500,">="&Q12)=0,_xlfn.MAXIFS(기준SD!$C$2:$C$500,기준SD!$E$2:$E$500,AA12),_xlfn.MINIFS(기준SD!$C$2:$C$500,기준SD!$E$2:$E$500,AA12,기준SD!$C$2:$C$500,">="&Q12))) | AD12: =IF(AB12="","",SUMIFS(기준SD!$D$2:$D$500,기준SD!$E$2:$E$500,AA12,기준SD!$C$2:$C$500,AB12)) | AE12: =IF(AC12="","",SUMIFS(기준SD!$D$2:$D$500,기준SD!$E$2:$E$500,AA12,기준SD!$C$2:$C$500,AC12))
A13: Fe | C13: Cr | P13: =COUNT(F13:O13) -> 0 | Q13: =IF(P13<2,"",AVERAGE(F13:O13)) | R13: =IF(P13<2,"",STDEV(F13:O13)) | S13: =IF(P13<2,"",IF(Q13=0,"",R13/Q13*100)) | T13: =IF(AB13="","",IF(AB13=AC13,AD13,AD13+(AE13-AD13)*(Q13-AB13)/(AC13-AB13))) | U13: =IF(OR(T13="",R13=""),"",IF(T13=0,"",R13/T13)) | V13: =IF(Q13="","",IF(T13="","기준없음",IF(R13<=T13*$C$2,"합격","불합격"))) | W13: =IF(OR(Q13="",D13=""),"",Q13-D13) | X13: =IF(W13="","",IF(E13<>"",E13,IF(T13="","",T13*$C$3))) | Y13: =IF(OR(W13="",X13=""),"",IF(ABS(W13)<=X13,"합격","불합격")) | Z13: =IF(OR(AA13="",Q13=""),"",IF(AB13="","기준SD 데이터 없음 ",IF(Q13<_xlfn.MINIFS(기준SD!$C$2:$C$500,기준SD!$E$2:$E$500,AA13),"최저 레벨 미만→최저 레벨 SD 적용 ",IF(Q13>_xlfn.MAXIFS(기준SD!$C$2:$C$500,기준SD!$E$2:$E$500,AA13),"최고 레벨 초과→최고 레벨 SD 적용 ","")))&IF(SUMIFS(원소정보!$E$2:$E$200,원소정보!$F$2:$F$200,AA13)>0,IF(Q13>SUMIFS(원소정보!$E$2:$E$200,원소정보!$F$2:$F$200,AA13),"검량범위 초과 ",""),"")&IF(SUMIFS(원소정보!$D$2:$D$200,원소정보!$F$2:$F$200,AA13)>0,IF(Q13<SUMIFS(원소정보!$D$2:$D$200,원소정보!$F$2:$F$200,AA13)/10000,"검출한계 미만",""),"")) | AA13: =IF(OR(A13="",C13=""),"",A13&"|"&C13) -> Fe|Cr | AB13: =IF(OR(AA13="",Q13=""),"",IF(COUNTIF(기준SD!$E$2:$E$500,AA13)=0,"",IF(COUNTIFS(기준SD!$E$2:$E$500,AA13,기준SD!$C$2:$C$500,"<="&Q13)=0,_xlfn.MINIFS(기준SD!$C$2:$C$500,기준SD!$E$2:$E$500,AA13),_xlfn.MAXIFS(기준SD!$C$2:$C$500,기준SD!$E$2:$E$500,AA13,기준SD!$C$2:$C$500,"<="&Q13)))) | AC13: =IF(AB13="","",IF(COUNTIFS(기준SD!$E$2:$E$500,AA13,기준SD!$C$2:$C$500,">="&Q13)=0,_xlfn.MAXIFS(기준SD!$C$2:$C$500,기준SD!$E$2:$E$500,AA13),_xlfn.MINIFS(기준SD!$C$2:$C$500,기준SD!$E$2:$E$500,AA13,기준SD!$C$2:$C$500,">="&Q13))) | AD13: =IF(AB13="","",SUMIFS(기준SD!$D$2:$D$500,기준SD!$E$2:$E$500,AA13,기준SD!$C$2:$C$500,AB13)) | AE13: =IF(AC13="","",SUMIFS(기준SD!$D$2:$D$500,기준SD!$E$2:$E$500,AA13,기준SD!$C$2:$C$500,AC13))
A14: Fe | C14: Cu | P14: =COUNT(F14:O14) -> 0 | Q14: =IF(P14<2,"",AVERAGE(F14:O14)) | R14: =IF(P14<2,"",STDEV(F14:O14)) | S14: =IF(P14<2,"",IF(Q14=0,"",R14/Q14*100)) | T14: =IF(AB14="","",IF(AB14=AC14,AD14,AD14+(AE14-AD14)*(Q14-AB14)/(AC14-AB14))) | U14: =IF(OR(T14="",R14=""),"",IF(T14=0,"",R14/T14)) | V14: =IF(Q14="","",IF(T14="","기준없음",IF(R14<=T14*$C$2,"합격","불합격"))) | W14: =IF(OR(Q14="",D14=""),"",Q14-D14) | X14: =IF(W14="","",IF(E14<>"",E14,IF(T14="","",T14*$C$3))) | Y14: =IF(OR(W14="",X14=""),"",IF(ABS(W14)<=X14,"합격","불합격")) | Z14: =IF(OR(AA14="",Q14=""),"",IF(AB14="","기준SD 데이터 없음 ",IF(Q14<_xlfn.MINIFS(기준SD!$C$2:$C$500,기준SD!$E$2:$E$500,AA14),"최저 레벨 미만→최저 레벨 SD 적용 ",IF(Q14>_xlfn.MAXIFS(기준SD!$C$2:$C$500,기준SD!$E$2:$E$500,AA14),"최고 레벨 초과→최고 레벨 SD 적용 ","")))&IF(SUMIFS(원소정보!$E$2:$E$200,원소정보!$F$2:$F$200,AA14)>0,IF(Q14>SUMIFS(원소정보!$E$2:$E$200,원소정보!$F$2:$F$200,AA14),"검량범위 초과 ",""),"")&IF(SUMIFS(원소정보!$D$2:$D$200,원소정보!$F$2:$F$200,AA14)>0,IF(Q14<SUMIFS(원소정보!$D$2:$D$200,원소정보!$F$2:$F$200,AA14)/10000,"검출한계 미만",""),"")) | AA14: =IF(OR(A14="",C14=""),"",A14&"|"&C14) -> Fe|Cu | AB14: =IF(OR(AA14="",Q14=""),"",IF(COUNTIF(기준SD!$E$2:$E$500,AA14)=0,"",IF(COUNTIFS(기준SD!$E$2:$E$500,AA14,기준SD!$C$2:$C$500,"<="&Q14)=0,_xlfn.MINIFS(기준SD!$C$2:$C$500,기준SD!$E$2:$E$500,AA14),_xlfn.MAXIFS(기준SD!$C$2:$C$500,기준SD!$E$2:$E$500,AA14,기준SD!$C$2:$C$500,"<="&Q14)))) | AC14: =IF(AB14="","",IF(COUNTIFS(기준SD!$E$2:$E$500,AA14,기준SD!$C$2:$C$500,">="&Q14)=0,_xlfn.MAXIFS(기준SD!$C$2:$C$500,기준SD!$E$2:$E$500,AA14),_xlfn.MINIFS(기준SD!$C$2:$C$500,기준SD!$E$2:$E$500,AA14,기준SD!$C$2:$C$500,">="&Q14))) | AD14: =IF(AB14="","",SUMIFS(기준SD!$D$2:$D$500,기준SD!$E$2:$E$500,AA14,기준SD!$C$2:$C$500,AB14)) | AE14: =IF(AC14="","",SUMIFS(기준SD!$D$2:$D$500,기준SD!$E$2:$E$500,AA14,기준SD!$C$2:$C$500,AC14))
A15: Fe | C15: Mg | P15: =COUNT(F15:O15) -> 0 | Q15: =IF(P15<2,"",AVERAGE(F15:O15)) | R15: =IF(P15<2,"",STDEV(F15:O15)) | S15: =IF(P15<2,"",IF(Q15=0,"",R15/Q15*100)) | T15: =IF(AB15="","",IF(AB15=AC15,AD15,AD15+(AE15-AD15)*(Q15-AB15)/(AC15-AB15))) | U15: =IF(OR(T15="",R15=""),"",IF(T15=0,"",R15/T15)) | V15: =IF(Q15="","",IF(T15="","기준없음",IF(R15<=T15*$C$2,"합격","불합격"))) | W15: =IF(OR(Q15="",D15=""),"",Q15-D15) | X15: =IF(W15="","",IF(E15<>"",E15,IF(T15="","",T15*$C$3))) | Y15: =IF(OR(W15="",X15=""),"",IF(ABS(W15)<=X15,"합격","불합격")) | Z15: =IF(OR(AA15="",Q15=""),"",IF(AB15="","기준SD 데이터 없음 ",IF(Q15<_xlfn.MINIFS(기준SD!$C$2:$C$500,기준SD!$E$2:$E$500,AA15),"최저 레벨 미만→최저 레벨 SD 적용 ",IF(Q15>_xlfn.MAXIFS(기준SD!$C$2:$C$500,기준SD!$E$2:$E$500,AA15),"최고 레벨 초과→최고 레벨 SD 적용 ","")))&IF(SUMIFS(원소정보!$E$2:$E$200,원소정보!$F$2:$F$200,AA15)>0,IF(Q15>SUMIFS(원소정보!$E$2:$E$200,원소정보!$F$2:$F$200,AA15),"검량범위 초과 ",""),"")&IF(SUMIFS(원소정보!$D$2:$D$200,원소정보!$F$2:$F$200,AA15)>0,IF(Q15<SUMIFS(원소정보!$D$2:$D$200,원소정보!$F$2:$F$200,AA15)/10000,"검출한계 미만",""),"")) | AA15: =IF(OR(A15="",C15=""),"",A15&"|"&C15) -> Fe|Mg | AB15: =IF(OR(AA15="",Q15=""),"",IF(COUNTIF(기준SD!$E$2:$E$500,AA15)=0,"",IF(COUNTIFS(기준SD!$E$2:$E$500,AA15,기준SD!$C$2:$C$500,"<="&Q15)=0,_xlfn.MINIFS(기준SD!$C$2:$C$500,기준SD!$E$2:$E$500,AA15),_xlfn.MAXIFS(기준SD!$C$2:$C$500,기준SD!$E$2:$E$500,AA15,기준SD!$C$2:$C$500,"<="&Q15)))) | AC15: =IF(AB15="","",IF(COUNTIFS(기준SD!$E$2:$E$500,AA15,기준SD!$C$2:$C$500,">="&Q15)=0,_xlfn.MAXIFS(기준SD!$C$2:$C$500,기준SD!$E$2:$E$500,AA15),_xlfn.MINIFS(기준SD!$C$2:$C$500,기준SD!$E$2:$E$500,AA15,기준SD!$C$2:$C$500,">="&Q15))) | AD15: =IF(AB15="","",SUMIFS(기준SD!$D$2:$D$500,기준SD!$E$2:$E$500,AA15,기준SD!$C$2:$C$500,AB15)) | AE15: =IF(AC15="","",SUMIFS(기준SD!$D$2:$D$500,기준SD!$E$2:$E$500,AA15,기준SD!$C$2:$C$500,AC15))
A16: Fe | C16: Mn | P16: =COUNT(F16:O16) -> 0 | Q16: =IF(P16<2,"",AVERAGE(F16:O16)) | R16: =IF(P16<2,"",STDEV(F16:O16)) | S16: =IF(P16<2,"",IF(Q16=0,"",R16/Q16*100)) | T16: =IF(AB16="","",IF(AB16=AC16,AD16,AD16+(AE16-AD16)*(Q16-AB16)/(AC16-AB16))) | U16: =IF(OR(T16="",R16=""),"",IF(T16=0,"",R16/T16)) | V16: =IF(Q16="","",IF(T16="","기준없음",IF(R16<=T16*$C$2,"합격","불합격"))) | W16: =IF(OR(Q16="",D16=""),"",Q16-D16) | X16: =IF(W16="","",IF(E16<>"",E16,IF(T16="","",T16*$C$3))) | Y16: =IF(OR(W16="",X16=""),"",IF(ABS(W16)<=X16,"합격","불합격")) | Z16: =IF(OR(AA16="",Q16=""),"",IF(AB16="","기준SD 데이터 없음 ",IF(Q16<_xlfn.MINIFS(기준SD!$C$2:$C$500,기준SD!$E$2:$E$500,AA16),"최저 레벨 미만→최저 레벨 SD 적용 ",IF(Q16>_xlfn.MAXIFS(기준SD!$C$2:$C$500,기준SD!$E$2:$E$500,AA16),"최고 레벨 초과→최고 레벨 SD 적용 ","")))&IF(SUMIFS(원소정보!$E$2:$E$200,원소정보!$F$2:$F$200,AA16)>0,IF(Q16>SUMIFS(원소정보!$E$2:$E$200,원소정보!$F$2:$F$200,AA16),"검량범위 초과 ",""),"")&IF(SUMIFS(원소정보!$D$2:$D$200,원소정보!$F$2:$F$200,AA16)>0,IF(Q16<SUMIFS(원소정보!$D$2:$D$200,원소정보!$F$2:$F$200,AA16)/10000,"검출한계 미만",""),"")) | AA16: =IF(OR(A16="",C16=""),"",A16&"|"&C16) -> Fe|Mn | AB16: =IF(OR(AA16="",Q16=""),"",IF(COUNTIF(기준SD!$E$2:$E$500,AA16)=0,"",IF(COUNTIFS(기준SD!$E$2:$E$500,AA16,기준SD!$C$2:$C$500,"<="&Q16)=0,_xlfn.MINIFS(기준SD!$C$2:$C$500,기준SD!$E$2:$E$500,AA16),_xlfn.MAXIFS(기준SD!$C$2:$C$500,기준SD!$E$2:$E$500,AA16,기준SD!$C$2:$C$500,"<="&Q16)))) | AC16: =IF(AB16="","",IF(COUNTIFS(기준SD!$E$2:$E$500,AA16,기준SD!$C$2:$C$500,">="&Q16)=0,_xlfn.MAXIFS(기준SD!$C$2:$C$500,기준SD!$E$2:$E$500,AA16),_xlfn.MINIFS(기준SD!$C$2:$C$500,기준SD!$E$2:$E$500,AA16,기준SD!$C$2:$C$500,">="&Q16))) | AD16: =IF(AB16="","",SUMIFS(기준SD!$D$2:$D$500,기준SD!$E$2:$E$500,AA16,기준SD!$C$2:$C$500,AB16)) | AE16: =IF(AC16="","",SUMIFS(기준SD!$D$2:$D$500,기준SD!$E$2:$E$500,AA16,기준SD!$C$2:$C$500,AC16))
A17: Fe | C17: Mo | P17: =COUNT(F17:O17) -> 0 | Q17: =IF(P17<2,"",AVERAGE(F17:O17)) | R17: =IF(P17<2,"",STDEV(F17:O17)) | S17: =IF(P17<2,"",IF(Q17=0,"",R17/Q17*100)) | T17: =IF(AB17="","",IF(AB17=AC17,AD17,AD17+(AE17-AD17)*(Q17-AB17)/(AC17-AB17))) | U17: =IF(OR(T17="",R17=""),"",IF(T17=0,"",R17/T17)) | V17: =IF(Q17="","",IF(T17="","기준없음",IF(R17<=T17*$C$2,"합격","불합격"))) | W17: =IF(OR(Q17="",D17=""),"",Q17-D17) | X17: =IF(W17="","",IF(E17<>"",E17,IF(T17="","",T17*$C$3))) | Y17: =IF(OR(W17="",X17=""),"",IF(ABS(W17)<=X17,"합격","불합격")) | Z17: =IF(OR(AA17="",Q17=""),"",IF(AB17="","기준SD 데이터 없음 ",IF(Q17<_xlfn.MINIFS(기준SD!$C$2:$C$500,기준SD!$E$2:$E$500,AA17),"최저 레벨 미만→최저 레벨 SD 적용 ",IF(Q17>_xlfn.MAXIFS(기준SD!$C$2:$C$500,기준SD!$E$2:$E$500,AA17),"최고 레벨 초과→최고 레벨 SD 적용 ","")))&IF(SUMIFS(원소정보!$E$2:$E$200,원소정보!$F$2:$F$200,AA17)>0,IF(Q17>SUMIFS(원소정보!$E$2:$E$200,원소정보!$F$2:$F$200,AA17),"검량범위 초과 ",""),"")&IF(SUMIFS(원소정보!$D$2:$D$200,원소정보!$F$2:$F$200,AA17)>0,IF(Q17<SUMIFS(원소정보!$D$2:$D$200,원소정보!$F$2:$F$200,AA17)/10000,"검출한계 미만",""),"")) | AA17: =IF(OR(A17="",C17=""),"",A17&"|"&C17) -> Fe|Mo | AB17: =IF(OR(AA17="",Q17=""),"",IF(COUNTIF(기준SD!$E$2:$E$500,AA17)=0,"",IF(COUNTIFS(기준SD!$E$2:$E$500,AA17,기준SD!$C$2:$C$500,"<="&Q17)=0,_xlfn.MINIFS(기준SD!$C$2:$C$500,기준SD!$E$2:$E$500,AA17),_xlfn.MAXIFS(기준SD!$C$2:$C$500,기준SD!$E$2:$E$500,AA17,기준SD!$C$2:$C$500,"<="&Q17)))) | AC17: =IF(AB17="","",IF(COUNTIFS(기준SD!$E$2:$E$500,AA17,기준SD!$C$2:$C$500,">="&Q17)=0,_xlfn.MAXIFS(기준SD!$C$2:$C$500,기준SD!$E$2:$E$500,AA17),_xlfn.MINIFS(기준SD!$C$2:$C$500,기준SD!$E$2:$E$500,AA17,기준SD!$C$2:$C$500,">="&Q17))) | AD17: =IF(AB17="","",SUMIFS(기준SD!$D$2:$D$500,기준SD!$E$2:$E$500,AA17,기준SD!$C$2:$C$500,AB17)) | AE17: =IF(AC17="","",SUMIFS(기준SD!$D$2:$D$500,기준SD!$E$2:$E$500,AA17,기준SD!$C$2:$C$500,AC17))
A18: Fe | C18: Nb | P18: =COUNT(F18:O18) -> 0 | Q18: =IF(P18<2,"",AVERAGE(F18:O18)) | R18: =IF(P18<2,"",STDEV(F18:O18)) | S18: =IF(P18<2,"",IF(Q18=0,"",R18/Q18*100)) | T18: =IF(AB18="","",IF(AB18=AC18,AD18,AD18+(AE18-AD18)*(Q18-AB18)/(AC18-AB18))) | U18: =IF(OR(T18="",R18=""),"",IF(T18=0,"",R18/T18)) | V18: =IF(Q18="","",IF(T18="","기준없음",IF(R18<=T18*$C$2,"합격","불합격"))) | W18: =IF(OR(Q18="",D18=""),"",Q18-D18) | X18: =IF(W18="","",IF(E18<>"",E18,IF(T18="","",T18*$C$3))) | Y18: =IF(OR(W18="",X18=""),"",IF(ABS(W18)<=X18,"합격","불합격")) | Z18: =IF(OR(AA18="",Q18=""),"",IF(AB18="","기준SD 데이터 없음 ",IF(Q18<_xlfn.MINIFS(기준SD!$C$2:$C$500,기준SD!$E$2:$E$500,AA18),"최저 레벨 미만→최저 레벨 SD 적용 ",IF(Q18>_xlfn.MAXIFS(기준SD!$C$2:$C$500,기준SD!$E$2:$E$500,AA18),"최고 레벨 초과→최고 레벨 SD 적용 ","")))&IF(SUMIFS(원소정보!$E$2:$E$200,원소정보!$F$2:$F$200,AA18)>0,IF(Q18>SUMIFS(원소정보!$E$2:$E$200,원소정보!$F$2:$F$200,AA18),"검량범위 초과 ",""),"")&IF(SUMIFS(원소정보!$D$2:$D$200,원소정보!$F$2:$F$200,AA18)>0,IF(Q18<SUMIFS(원소정보!$D$2:$D$200,원소정보!$F$2:$F$200,AA18)/10000,"검출한계 미만",""),"")) | AA18: =IF(OR(A18="",C18=""),"",A18&"|"&C18) -> Fe|Nb | AB18: =IF(OR(AA18="",Q18=""),"",IF(COUNTIF(기준SD!$E$2:$E$500,AA18)=0,"",IF(COUNTIFS(기준SD!$E$2:$E$500,AA18,기준SD!$C$2:$C$500,"<="&Q18)=0,_xlfn.MINIFS(기준SD!$C$2:$C$500,기준SD!$E$2:$E$500,AA18),_xlfn.MAXIFS(기준SD!$C$2:$C$500,기준SD!$E$2:$E$500,AA18,기준SD!$C$2:$C$500,"<="&Q18)))) | AC18: =IF(AB18="","",IF(COUNTIFS(기준SD!$E$2:$E$500,AA18,기준SD!$C$2:$C$500,">="&Q18)=0,_xlfn.MAXIFS(기준SD!$C$2:$C$500,기준SD!$E$2:$E$500,AA18),_xlfn.MINIFS(기준SD!$C$2:$C$500,기준SD!$E$2:$E$500,AA18,기준SD!$C$2:$C$500,">="&Q18))) | AD18: =IF(AB18="","",SUMIFS(기준SD!$D$2:$D$500,기준SD!$E$2:$E$500,AA18,기준SD!$C$2:$C$500,AB18)) | AE18: =IF(AC18="","",SUMIFS(기준SD!$D$2:$D$500,기준SD!$E$2:$E$500,AA18,기준SD!$C$2:$C$500,AC18))
... A24: Fe | C24: Sn | P24: =COUNT(F24:O24) -> 0 | Q24: =IF(P24<2,"",AVERAGE(F24:O24)) | R24: =IF(P24<2,"",STDEV(F24:O24)) | S24: =IF(P24<2,"",IF(Q24=0,"",R24/Q24*100)) | T24: =IF(AB24="","",IF(AB24=AC24,AD24,AD24+(AE24-AD24)*(Q24-AB24)/(AC24-AB24))) | U24: =IF(OR(T24="",R24=""),"",IF(T24=0,"",R24/T24)) | V24: =IF(Q24="","",IF(T24="","기준없음",IF(R24<=T24*$C$2,"합격","불합격"))) | W24: =IF(OR(Q24="",D24=""),"",Q24-D24) | X24: =IF(W24="","",IF(E24<>"",E24,IF(T24="","",T24*$C$3))) | Y24: =IF(OR(W24="",X24=""),"",IF(ABS(W24)<=X24,"합격","불합격")) | Z24: =IF(OR(AA24="",Q24=""),"",IF(AB24="","기준SD 데이터 없음 ",IF(Q24<_xlfn.MINIFS(기준SD!$C$2:$C$500,기준SD!$E$2:$E$500,AA24),"최저 레벨 미만→최저 레벨 SD 적용 ",IF(Q24>_xlfn.MAXIFS(기준SD!$C$2:$C$500,기준SD!$E$2:$E$500,AA24),"최고 레벨 초과→최고 레벨 SD 적용 ","")))&IF(SUMIFS(원소정보!$E$2:$E$200,원소정보!$F$2:$F$200,AA24)>0,IF(Q24>SUMIFS(원소정보!$E$2:$E$200,원소정보!$F$2:$F$200,AA24),"검량범위 초과 ",""),"")&IF(SUMIFS(원소정보!$D$2:$D$200,원소정보!$F$2:$F$200,AA24)>0,IF(Q24<SUMIFS(원소정보!$D$2:$D$200,원소정보!$F$2:$F$200,AA24)/10000,"검출한계 미만",""),"")) | AA24: =IF(OR(A24="",C24=""),"",A24&"|"&C24) -> Fe|Sn | AB24: =IF(OR(AA24="",Q24=""),"",IF(COUNTIF(기준SD!$E$2:$E$500,AA24)=0,"",IF(COUNTIFS(기준SD!$E$2:$E$500,AA24,기준SD!$C$2:$C$500,"<="&Q24)=0,_xlfn.MINIFS(기준SD!$C$2:$C$500,기준SD!$E$2:$E$500,AA24),_xlfn.MAXIFS(기준SD!$C$2:$C$500,기준SD!$E$2:$E$500,AA24,기준SD!$C$2:$C$500,"<="&Q24)))) | AC24: =IF(AB24="","",IF(COUNTIFS(기준SD!$E$2:$E$500,AA24,기준SD!$C$2:$C$500,">="&Q24)=0,_xlfn.MAXIFS(기준SD!$C$2:$C$500,기준SD!$E$2:$E$500,AA24),_xlfn.MINIFS(기준SD!$C$2:$C$500,기준SD!$E$2:$E$500,AA24,기준SD!$C$2:$C$500,">="&Q24))) | AD24: =IF(AB24="","",SUMIFS(기준SD!$D$2:$D$500,기준SD!$E$2:$E$500,AA24,기준SD!$C$2:$C$500,AB24)) | AE24: =IF(AC24="","",SUMIFS(기준SD!$D$2:$D$500,기준SD!$E$2:$E$500,AA24,기준SD!$C$2:$C$500,AC24))
P25: =COUNT(F25:O25) -> 0 | Q25: =IF(P25<2,"",AVERAGE(F25:O25)) | R25: =IF(P25<2,"",STDEV(F25:O25)) | S25: =IF(P25<2,"",IF(Q25=0,"",R25/Q25*100)) | T25: =IF(AB25="","",IF(AB25=AC25,AD25,AD25+(AE25-AD25)*(Q25-AB25)/(AC25-AB25))) | U25: =IF(OR(T25="",R25=""),"",IF(T25=0,"",R25/T25)) | V25: =IF(Q25="","",IF(T25="","기준없음",IF(R25<=T25*$C$2,"합격","불합격"))) | W25: =IF(OR(Q25="",D25=""),"",Q25-D25) | X25: =IF(W25="","",IF(E25<>"",E25,IF(T25="","",T25*$C$3))) | Y25: =IF(OR(W25="",X25=""),"",IF(ABS(W25)<=X25,"합격","불합격")) | Z25: =IF(OR(AA25="",Q25=""),"",IF(AB25="","기준SD 데이터 없음 ",IF(Q25<_xlfn.MINIFS(기준SD!$C$2:$C$500,기준SD!$E$2:$E$500,AA25),"최저 레벨 미만→최저 레벨 SD 적용 ",IF(Q25>_xlfn.MAXIFS(기준SD!$C$2:$C$500,기준SD!$E$2:$E$500,AA25),"최고 레벨 초과→최고 레벨 SD 적용 ","")))&IF(SUMIFS(원소정보!$E$2:$E$200,원소정보!$F$2:$F$200,AA25)>0,IF(Q25>SUMIFS(원소정보!$E$2:$E$200,원소정보!$F$2:$F$200,AA25),"검량범위 초과 ",""),"")&IF(SUMIFS(원소정보!$D$2:$D$200,원소정보!$F$2:$F$200,AA25)>0,IF(Q25<SUMIFS(원소정보!$D$2:$D$200,원소정보!$F$2:$F$200,AA25)/10000,"검출한계 미만",""),"")) | AA25: =IF(OR(A25="",C25=""),"",A25&"|"&C25) | AB25: =IF(OR(AA25="",Q25=""),"",IF(COUNTIF(기준SD!$E$2:$E$500,AA25)=0,"",IF(COUNTIFS(기준SD!$E$2:$E$500,AA25,기준SD!$C$2:$C$500,"<="&Q25)=0,_xlfn.MINIFS(기준SD!$C$2:$C$500,기준SD!$E$2:$E$500,AA25),_xlfn.MAXIFS(기준SD!$C$2:$C$500,기준SD!$E$2:$E$500,AA25,기준SD!$C$2:$C$500,"<="&Q25)))) | AC25: =IF(AB25="","",IF(COUNTIFS(기준SD!$E$2:$E$500,AA25,기준SD!$C$2:$C$500,">="&Q25)=0,_xlfn.MAXIFS(기준SD!$C$2:$C$500,기준SD!$E$2:$E$500,AA25),_xlfn.MINIFS(기준SD!$C$2:$C$500,기준SD!$E$2:$E$500,AA25,기준SD!$C$2:$C$500,">="&Q25))) | AD25: =IF(AB25="","",SUMIFS(기준SD!$D$2:$D$500,기준SD!$E$2:$E$500,AA25,기준SD!$C$2:$C$500,AB25)) | AE25: =IF(AC25="","",SUMIFS(기준SD!$D$2:$D$500,기준SD!$E$2:$E$500,AA25,기준SD!$C$2:$C$500,AC25))
P26: =COUNT(F26:O26) -> 0 | Q26: =IF(P26<2,"",AVERAGE(F26:O26)) | R26: =IF(P26<2,"",STDEV(F26:O26)) | S26: =IF(P26<2,"",IF(Q26=0,"",R26/Q26*100)) | T26: =IF(AB26="","",IF(AB26=AC26,AD26,AD26+(AE26-AD26)*(Q26-AB26)/(AC26-AB26))) | U26: =IF(OR(T26="",R26=""),"",IF(T26=0,"",R26/T26)) | V26: =IF(Q26="","",IF(T26="","기준없음",IF(R26<=T26*$C$2,"합격","불합격"))) | W26: =IF(OR(Q26="",D26=""),"",Q26-D26) | X26: =IF(W26="","",IF(E26<>"",E26,IF(T26="","",T26*$C$3))) | Y26: =IF(OR(W26="",X26=""),"",IF(ABS(W26)<=X26,"합격","불합격")) | Z26: =IF(OR(AA26="",Q26=""),"",IF(AB26="","기준SD 데이터 없음 ",IF(Q26<_xlfn.MINIFS(기준SD!$C$2:$C$500,기준SD!$E$2:$E$500,AA26),"최저 레벨 미만→최저 레벨 SD 적용 ",IF(Q26>_xlfn.MAXIFS(기준SD!$C$2:$C$500,기준SD!$E$2:$E$500,AA26),"최고 레벨 초과→최고 레벨 SD 적용 ","")))&IF(SUMIFS(원소정보!$E$2:$E$200,원소정보!$F$2:$F$200,AA26)>0,IF(Q26>SUMIFS(원소정보!$E$2:$E$200,원소정보!$F$2:$F$200,AA26),"검량범위 초과 ",""),"")&IF(SUMIFS(원소정보!$D$2:$D$200,원소정보!$F$2:$F$200,AA26)>0,IF(Q26<SUMIFS(원소정보!$D$2:$D$200,원소정보!$F$2:$F$200,AA26)/10000,"검출한계 미만",""),"")) | AA26: =IF(OR(A26="",C26=""),"",A26&"|"&C26) | AB26: =IF(OR(AA26="",Q26=""),"",IF(COUNTIF(기준SD!$E$2:$E$500,AA26)=0,"",IF(COUNTIFS(기준SD!$E$2:$E$500,AA26,기준SD!$C$2:$C$500,"<="&Q26)=0,_xlfn.MINIFS(기준SD!$C$2:$C$500,기준SD!$E$2:$E$500,AA26),_xlfn.MAXIFS(기준SD!$C$2:$C$500,기준SD!$E$2:$E$500,AA26,기준SD!$C$2:$C$500,"<="&Q26)))) | AC26: =IF(AB26="","",IF(COUNTIFS(기준SD!$E$2:$E$500,AA26,기준SD!$C$2:$C$500,">="&Q26)=0,_xlfn.MAXIFS(기준SD!$C$2:$C$500,기준SD!$E$2:$E$500,AA26),_xlfn.MINIFS(기준SD!$C$2:$C$500,기준SD!$E$2:$E$500,AA26,기준SD!$C$2:$C$500,">="&Q26))) | AD26: =IF(AB26="","",SUMIFS(기준SD!$D$2:$D$500,기준SD!$E$2:$E$500,AA26,기준SD!$C$2:$C$500,AB26)) | AE26: =IF(AC26="","",SUMIFS(기준SD!$D$2:$D$500,기준SD!$E$2:$E$500,AA26,기준SD!$C$2:$C$500,AC26))
P27: =COUNT(F27:O27) -> 0 | Q27: =IF(P27<2,"",AVERAGE(F27:O27)) | R27: =IF(P27<2,"",STDEV(F27:O27)) | S27: =IF(P27<2,"",IF(Q27=0,"",R27/Q27*100)) | T27: =IF(AB27="","",IF(AB27=AC27,AD27,AD27+(AE27-AD27)*(Q27-AB27)/(AC27-AB27))) | U27: =IF(OR(T27="",R27=""),"",IF(T27=0,"",R27/T27)) | V27: =IF(Q27="","",IF(T27="","기준없음",IF(R27<=T27*$C$2,"합격","불합격"))) | W27: =IF(OR(Q27="",D27=""),"",Q27-D27) | X27: =IF(W27="","",IF(E27<>"",E27,IF(T27="","",T27*$C$3))) | Y27: =IF(OR(W27="",X27=""),"",IF(ABS(W27)<=X27,"합격","불합격")) | Z27: =IF(OR(AA27="",Q27=""),"",IF(AB27="","기준SD 데이터 없음 ",IF(Q27<_xlfn.MINIFS(기준SD!$C$2:$C$500,기준SD!$E$2:$E$500,AA27),"최저 레벨 미만→최저 레벨 SD 적용 ",IF(Q27>_xlfn.MAXIFS(기준SD!$C$2:$C$500,기준SD!$E$2:$E$500,AA27),"최고 레벨 초과→최고 레벨 SD 적용 ","")))&IF(SUMIFS(원소정보!$E$2:$E$200,원소정보!$F$2:$F$200,AA27)>0,IF(Q27>SUMIFS(원소정보!$E$2:$E$200,원소정보!$F$2:$F$200,AA27),"검량범위 초과 ",""),"")&IF(SUMIFS(원소정보!$D$2:$D$200,원소정보!$F$2:$F$200,AA27)>0,IF(Q27<SUMIFS(원소정보!$D$2:$D$200,원소정보!$F$2:$F$200,AA27)/10000,"검출한계 미만",""),"")) | AA27: =IF(OR(A27="",C27=""),"",A27&"|"&C27) | AB27: =IF(OR(AA27="",Q27=""),"",IF(COUNTIF(기준SD!$E$2:$E$500,AA27)=0,"",IF(COUNTIFS(기준SD!$E$2:$E$500,AA27,기준SD!$C$2:$C$500,"<="&Q27)=0,_xlfn.MINIFS(기준SD!$C$2:$C$500,기준SD!$E$2:$E$500,AA27),_xlfn.MAXIFS(기준SD!$C$2:$C$500,기준SD!$E$2:$E$500,AA27,기준SD!$C$2:$C$500,"<="&Q27)))) | AC27: =IF(AB27="","",IF(COUNTIFS(기준SD!$E$2:$E$500,AA27,기준SD!$C$2:$C$500,">="&Q27)=0,_xlfn.MAXIFS(기준SD!$C$2:$C$500,기준SD!$E$2:$E$500,AA27),_xlfn.MINIFS(기준SD!$C$2:$C$500,기준SD!$E$2:$E$500,AA27,기준SD!$C$2:$C$500,">="&Q27))) | AD27: =IF(AB27="","",SUMIFS(기준SD!$D$2:$D$500,기준SD!$E$2:$E$500,AA27,기준SD!$C$2:$C$500,AB27)) | AE27: =IF(AC27="","",SUMIFS(기준SD!$D$2:$D$500,기준SD!$E$2:$E$500,AA27,기준SD!$C$2:$C$500,AC27))
P28: =COUNT(F28:O28) -> 0 | Q28: =IF(P28<2,"",AVERAGE(F28:O28)) | R28: =IF(P28<2,"",STDEV(F28:O28)) | S28: =IF(P28<2,"",IF(Q28=0,"",R28/Q28*100)) | T28: =IF(AB28="","",IF(AB28=AC28,AD28,AD28+(AE28-AD28)*(Q28-AB28)/(AC28-AB28))) | U28: =IF(OR(T28="",R28=""),"",IF(T28=0,"",R28/T28)) | V28: =IF(Q28="","",IF(T28="","기준없음",IF(R28<=T28*$C$2,"합격","불합격"))) | W28: =IF(OR(Q28="",D28=""),"",Q28-D28) | X28: =IF(W28="","",IF(E28<>"",E28,IF(T28="","",T28*$C$3))) | Y28: =IF(OR(W28="",X28=""),"",IF(ABS(W28)<=X28,"합격","불합격")) | Z28: =IF(OR(AA28="",Q28=""),"",IF(AB28="","기준SD 데이터 없음 ",IF(Q28<_xlfn.MINIFS(기준SD!$C$2:$C$500,기준SD!$E$2:$E$500,AA28),"최저 레벨 미만→최저 레벨 SD 적용 ",IF(Q28>_xlfn.MAXIFS(기준SD!$C$2:$C$500,기준SD!$E$2:$E$500,AA28),"최고 레벨 초과→최고 레벨 SD 적용 ","")))&IF(SUMIFS(원소정보!$E$2:$E$200,원소정보!$F$2:$F$200,AA28)>0,IF(Q28>SUMIFS(원소정보!$E$2:$E$200,원소정보!$F$2:$F$200,AA28),"검량범위 초과 ",""),"")&IF(SUMIFS(원소정보!$D$2:$D$200,원소정보!$F$2:$F$200,AA28)>0,IF(Q28<SUMIFS(원소정보!$D$2:$D$200,원소정보!$F$2:$F$200,AA28)/10000,"검출한계 미만",""),"")) | AA28: =IF(OR(A28="",C28=""),"",A28&"|"&C28) | AB28: =IF(OR(AA28="",Q28=""),"",IF(COUNTIF(기준SD!$E$2:$E$500,AA28)=0,"",IF(COUNTIFS(기준SD!$E$2:$E$500,AA28,기준SD!$C$2:$C$500,"<="&Q28)=0,_xlfn.MINIFS(기준SD!$C$2:$C$500,기준SD!$E$2:$E$500,AA28),_xlfn.MAXIFS(기준SD!$C$2:$C$500,기준SD!$E$2:$E$500,AA28,기준SD!$C$2:$C$500,"<="&Q28)))) | AC28: =IF(AB28="","",IF(COUNTIFS(기준SD!$E$2:$E$500,AA28,기준SD!$C$2:$C$500,">="&Q28)=0,_xlfn.MAXIFS(기준SD!$C$2:$C$500,기준SD!$E$2:$E$500,AA28),_xlfn.MINIFS(기준SD!$C$2:$C$500,기준SD!$E$2:$E$500,AA28,기준SD!$C$2:$C$500,">="&Q28))) | AD28: =IF(AB28="","",SUMIFS(기준SD!$D$2:$D$500,기준SD!$E$2:$E$500,AA28,기준SD!$C$2:$C$500,AB28)) | AE28: =IF(AC28="","",SUMIFS(기준SD!$D$2:$D$500,기준SD!$E$2:$E$500,AA28,기준SD!$C$2:$C$500,AC28))
P29: =COUNT(F29:O29) -> 0 | Q29: =IF(P29<2,"",AVERAGE(F29:O29)) | R29: =IF(P29<2,"",STDEV(F29:O29)) | S29: =IF(P29<2,"",IF(Q29=0,"",R29/Q29*100)) | T29: =IF(AB29="","",IF(AB29=AC29,AD29,AD29+(AE29-AD29)*(Q29-AB29)/(AC29-AB29))) | U29: =IF(OR(T29="",R29=""),"",IF(T29=0,"",R29/T29)) | V29: =IF(Q29="","",IF(T29="","기준없음",IF(R29<=T29*$C$2,"합격","불합격"))) | W29: =IF(OR(Q29="",D29=""),"",Q29-D29) | X29: =IF(W29="","",IF(E29<>"",E29,IF(T29="","",T29*$C$3))) | Y29: =IF(OR(W29="",X29=""),"",IF(ABS(W29)<=X29,"합격","불합격")) | Z29: =IF(OR(AA29="",Q29=""),"",IF(AB29="","기준SD 데이터 없음 ",IF(Q29<_xlfn.MINIFS(기준SD!$C$2:$C$500,기준SD!$E$2:$E$500,AA29),"최저 레벨 미만→최저 레벨 SD 적용 ",IF(Q29>_xlfn.MAXIFS(기준SD!$C$2:$C$500,기준SD!$E$2:$E$500,AA29),"최고 레벨 초과→최고 레벨 SD 적용 ","")))&IF(SUMIFS(원소정보!$E$2:$E$200,원소정보!$F$2:$F$200,AA29)>0,IF(Q29>SUMIFS(원소정보!$E$2:$E$200,원소정보!$F$2:$F$200,AA29),"검량범위 초과 ",""),"")&IF(SUMIFS(원소정보!$D$2:$D$200,원소정보!$F$2:$F$200,AA29)>0,IF(Q29<SUMIFS(원소정보!$D$2:$D$200,원소정보!$F$2:$F$200,AA29)/10000,"검출한계 미만",""),"")) | AA29: =IF(OR(A29="",C29=""),"",A29&"|"&C29) | AB29: =IF(OR(AA29="",Q29=""),"",IF(COUNTIF(기준SD!$E$2:$E$500,AA29)=0,"",IF(COUNTIFS(기준SD!$E$2:$E$500,AA29,기준SD!$C$2:$C$500,"<="&Q29)=0,_xlfn.MINIFS(기준SD!$C$2:$C$500,기준SD!$E$2:$E$500,AA29),_xlfn.MAXIFS(기준SD!$C$2:$C$500,기준SD!$E$2:$E$500,AA29,기준SD!$C$2:$C$500,"<="&Q29)))) | AC29: =IF(AB29="","",IF(COUNTIFS(기준SD!$E$2:$E$500,AA29,기준SD!$C$2:$C$500,">="&Q29)=0,_xlfn.MAXIFS(기준SD!$C$2:$C$500,기준SD!$E$2:$E$500,AA29),_xlfn.MINIFS(기준SD!$C$2:$C$500,기준SD!$E$2:$E$500,AA29,기준SD!$C$2:$C$500,">="&Q29))) | AD29: =IF(AB29="","",SUMIFS(기준SD!$D$2:$D$500,기준SD!$E$2:$E$500,AA29,기준SD!$C$2:$C$500,AB29)) | AE29: =IF(AC29="","",SUMIFS(기준SD!$D$2:$D$500,기준SD!$E$2:$E$500,AA29,기준SD!$C$2:$C$500,AC29))
P30: =COUNT(F30:O30) -> 0 | Q30: =IF(P30<2,"",AVERAGE(F30:O30)) | R30: =IF(P30<2,"",STDEV(F30:O30)) | S30: =IF(P30<2,"",IF(Q30=0,"",R30/Q30*100)) | T30: =IF(AB30="","",IF(AB30=AC30,AD30,AD30+(AE30-AD30)*(Q30-AB30)/(AC30-AB30))) | U30: =IF(OR(T30="",R30=""),"",IF(T30=0,"",R30/T30)) | V30: =IF(Q30="","",IF(T30="","기준없음",IF(R30<=T30*$C$2,"합격","불합격"))) | W30: =IF(OR(Q30="",D30=""),"",Q30-D30) | X30: =IF(W30="","",IF(E30<>"",E30,IF(T30="","",T30*$C$3))) | Y30: =IF(OR(W30="",X30=""),"",IF(ABS(W30)<=X30,"합격","불합격")) | Z30: =IF(OR(AA30="",Q30=""),"",IF(AB30="","기준SD 데이터 없음 ",IF(Q30<_xlfn.MINIFS(기준SD!$C$2:$C$500,기준SD!$E$2:$E$500,AA30),"최저 레벨 미만→최저 레벨 SD 적용 ",IF(Q30>_xlfn.MAXIFS(기준SD!$C$2:$C$500,기준SD!$E$2:$E$500,AA30),"최고 레벨 초과→최고 레벨 SD 적용 ","")))&IF(SUMIFS(원소정보!$E$2:$E$200,원소정보!$F$2:$F$200,AA30)>0,IF(Q30>SUMIFS(원소정보!$E$2:$E$200,원소정보!$F$2:$F$200,AA30),"검량범위 초과 ",""),"")&IF(SUMIFS(원소정보!$D$2:$D$200,원소정보!$F$2:$F$200,AA30)>0,IF(Q30<SUMIFS(원소정보!$D$2:$D$200,원소정보!$F$2:$F$200,AA30)/10000,"검출한계 미만",""),"")) | AA30: =IF(OR(A30="",C30=""),"",A30&"|"&C30) | AB30: =IF(OR(AA30="",Q30=""),"",IF(COUNTIF(기준SD!$E$2:$E$500,AA30)=0,"",IF(COUNTIFS(기준SD!$E$2:$E$500,AA30,기준SD!$C$2:$C$500,"<="&Q30)=0,_xlfn.MINIFS(기준SD!$C$2:$C$500,기준SD!$E$2:$E$500,AA30),_xlfn.MAXIFS(기준SD!$C$2:$C$500,기준SD!$E$2:$E$500,AA30,기준SD!$C$2:$C$500,"<="&Q30)))) | AC30: =IF(AB30="","",IF(COUNTIFS(기준SD!$E$2:$E$500,AA30,기준SD!$C$2:$C$500,">="&Q30)=0,_xlfn.MAXIFS(기준SD!$C$2:$C$500,기준SD!$E$2:$E$500,AA30),_xlfn.MINIFS(기준SD!$C$2:$C$500,기준SD!$E$2:$E$500,AA30,기준SD!$C$2:$C$500,">="&Q30))) | AD30: =IF(AB30="","",SUMIFS(기준SD!$D$2:$D$500,기준SD!$E$2:$E$500,AA30,기준SD!$C$2:$C$500,AB30)) | AE30: =IF(AC30="","",SUMIFS(기준SD!$D$2:$D$500,기준SD!$E$2:$E$500,AA30,기준SD!$C$2:$C$500,AC30))
P31: =COUNT(F31:O31) -> 0 | Q31: =IF(P31<2,"",AVERAGE(F31:O31)) | R31: =IF(P31<2,"",STDEV(F31:O31)) | S31: =IF(P31<2,"",IF(Q31=0,"",R31/Q31*100)) | T31: =IF(AB31="","",IF(AB31=AC31,AD31,AD31+(AE31-AD31)*(Q31-AB31)/(AC31-AB31))) | U31: =IF(OR(T31="",R31=""),"",IF(T31=0,"",R31/T31)) | V31: =IF(Q31="","",IF(T31="","기준없음",IF(R31<=T31*$C$2,"합격","불합격"))) | W31: =IF(OR(Q31="",D31=""),"",Q31-D31) | X31: =IF(W31="","",IF(E31<>"",E31,IF(T31="","",T31*$C$3))) | Y31: =IF(OR(W31="",X31=""),"",IF(ABS(W31)<=X31,"합격","불합격")) | Z31: =IF(OR(AA31="",Q31=""),"",IF(AB31="","기준SD 데이터 없음 ",IF(Q31<_xlfn.MINIFS(기준SD!$C$2:$C$500,기준SD!$E$2:$E$500,AA31),"최저 레벨 미만→최저 레벨 SD 적용 ",IF(Q31>_xlfn.MAXIFS(기준SD!$C$2:$C$500,기준SD!$E$2:$E$500,AA31),"최고 레벨 초과→최고 레벨 SD 적용 ","")))&IF(SUMIFS(원소정보!$E$2:$E$200,원소정보!$F$2:$F$200,AA31)>0,IF(Q31>SUMIFS(원소정보!$E$2:$E$200,원소정보!$F$2:$F$200,AA31),"검량범위 초과 ",""),"")&IF(SUMIFS(원소정보!$D$2:$D$200,원소정보!$F$2:$F$200,AA31)>0,IF(Q31<SUMIFS(원소정보!$D$2:$D$200,원소정보!$F$2:$F$200,AA31)/10000,"검출한계 미만",""),"")) | AA31: =IF(OR(A31="",C31=""),"",A31&"|"&C31) | AB31: =IF(OR(AA31="",Q31=""),"",IF(COUNTIF(기준SD!$E$2:$E$500,AA31)=0,"",IF(COUNTIFS(기준SD!$E$2:$E$500,AA31,기준SD!$C$2:$C$500,"<="&Q31)=0,_xlfn.MINIFS(기준SD!$C$2:$C$500,기준SD!$E$2:$E$500,AA31),_xlfn.MAXIFS(기준SD!$C$2:$C$500,기준SD!$E$2:$E$500,AA31,기준SD!$C$2:$C$500,"<="&Q31)))) | AC31: =IF(AB31="","",IF(COUNTIFS(기준SD!$E$2:$E$500,AA31,기준SD!$C$2:$C$500,">="&Q31)=0,_xlfn.MAXIFS(기준SD!$C$2:$C$500,기준SD!$E$2:$E$500,AA31),_xlfn.MINIFS(기준SD!$C$2:$C$500,기준SD!$E$2:$E$500,AA31,기준SD!$C$2:$C$500,">="&Q31))) | AD31: =IF(AB31="","",SUMIFS(기준SD!$D$2:$D$500,기준SD!$E$2:$E$500,AA31,기준SD!$C$2:$C$500,AB31)) | AE31: =IF(AC31="","",SUMIFS(기준SD!$D$2:$D$500,기준SD!$E$2:$E$500,AA31,기준SD!$C$2:$C$500,AC31))
P32: =COUNT(F32:O32) -> 0 | Q32: =IF(P32<2,"",AVERAGE(F32:O32)) | R32: =IF(P32<2,"",STDEV(F32:O32)) | S32: =IF(P32<2,"",IF(Q32=0,"",R32/Q32*100)) | T32: =IF(AB32="","",IF(AB32=AC32,AD32,AD32+(AE32-AD32)*(Q32-AB32)/(AC32-AB32))) | U32: =IF(OR(T32="",R32=""),"",IF(T32=0,"",R32/T32)) | V32: =IF(Q32="","",IF(T32="","기준없음",IF(R32<=T32*$C$2,"합격","불합격"))) | W32: =IF(OR(Q32="",D32=""),"",Q32-D32) | X32: =IF(W32="","",IF(E32<>"",E32,IF(T32="","",T32*$C$3))) | Y32: =IF(OR(W32="",X32=""),"",IF(ABS(W32)<=X32,"합격","불합격")) | Z32: =IF(OR(AA32="",Q32=""),"",IF(AB32="","기준SD 데이터 없음 ",IF(Q32<_xlfn.MINIFS(기준SD!$C$2:$C$500,기준SD!$E$2:$E$500,AA32),"최저 레벨 미만→최저 레벨 SD 적용 ",IF(Q32>_xlfn.MAXIFS(기준SD!$C$2:$C$500,기준SD!$E$2:$E$500,AA32),"최고 레벨 초과→최고 레벨 SD 적용 ","")))&IF(SUMIFS(원소정보!$E$2:$E$200,원소정보!$F$2:$F$200,AA32)>0,IF(Q32>SUMIFS(원소정보!$E$2:$E$200,원소정보!$F$2:$F$200,AA32),"검량범위 초과 ",""),"")&IF(SUMIFS(원소정보!$D$2:$D$200,원소정보!$F$2:$F$200,AA32)>0,IF(Q32<SUMIFS(원소정보!$D$2:$D$200,원소정보!$F$2:$F$200,AA32)/10000,"검출한계 미만",""),"")) | AA32: =IF(OR(A32="",C32=""),"",A32&"|"&C32) | AB32: =IF(OR(AA32="",Q32=""),"",IF(COUNTIF(기준SD!$E$2:$E$500,AA32)=0,"",IF(COUNTIFS(기준SD!$E$2:$E$500,AA32,기준SD!$C$2:$C$500,"<="&Q32)=0,_xlfn.MINIFS(기준SD!$C$2:$C$500,기준SD!$E$2:$E$500,AA32),_xlfn.MAXIFS(기준SD!$C$2:$C$500,기준SD!$E$2:$E$500,AA32,기준SD!$C$2:$C$500,"<="&Q32)))) | AC32: =IF(AB32="","",IF(COUNTIFS(기준SD!$E$2:$E$500,AA32,기준SD!$C$2:$C$500,">="&Q32)=0,_xlfn.MAXIFS(기준SD!$C$2:$C$500,기준SD!$E$2:$E$500,AA32),_xlfn.MINIFS(기준SD!$C$2:$C$500,기준SD!$E$2:$E$500,AA32,기준SD!$C$2:$C$500,">="&Q32))) | AD32: =IF(AB32="","",SUMIFS(기준SD!$D$2:$D$500,기준SD!$E$2:$E$500,AA32,기준SD!$C$2:$C$500,AB32)) | AE32: =IF(AC32="","",SUMIFS(기준SD!$D$2:$D$500,기준SD!$E$2:$E$500,AA32,기준SD!$C$2:$C$500,AC32))
P33: =COUNT(F33:O33) -> 0 | Q33: =IF(P33<2,"",AVERAGE(F33:O33)) | R33: =IF(P33<2,"",STDEV(F33:O33)) | S33: =IF(P33<2,"",IF(Q33=0,"",R33/Q33*100)) | T33: =IF(AB33="","",IF(AB33=AC33,AD33,AD33+(AE33-AD33)*(Q33-AB33)/(AC33-AB33))) | U33: =IF(OR(T33="",R33=""),"",IF(T33=0,"",R33/T33)) | V33: =IF(Q33="","",IF(T33="","기준없음",IF(R33<=T33*$C$2,"합격","불합격"))) | W33: =IF(OR(Q33="",D33=""),"",Q33-D33) | X33: =IF(W33="","",IF(E33<>"",E33,IF(T33="","",T33*$C$3))) | Y33: =IF(OR(W33="",X33=""),"",IF(ABS(W33)<=X33,"합격","불합격")) | Z33: =IF(OR(AA33="",Q33=""),"",IF(AB33="","기준SD 데이터 없음 ",IF(Q33<_xlfn.MINIFS(기준SD!$C$2:$C$500,기준SD!$E$2:$E$500,AA33),"최저 레벨 미만→최저 레벨 SD 적용 ",IF(Q33>_xlfn.MAXIFS(기준SD!$C$2:$C$500,기준SD!$E$2:$E$500,AA33),"최고 레벨 초과→최고 레벨 SD 적용 ","")))&IF(SUMIFS(원소정보!$E$2:$E$200,원소정보!$F$2:$F$200,AA33)>0,IF(Q33>SUMIFS(원소정보!$E$2:$E$200,원소정보!$F$2:$F$200,AA33),"검량범위 초과 ",""),"")&IF(SUMIFS(원소정보!$D$2:$D$200,원소정보!$F$2:$F$200,AA33)>0,IF(Q33<SUMIFS(원소정보!$D$2:$D$200,원소정보!$F$2:$F$200,AA33)/10000,"검출한계 미만",""),"")) | AA33: =IF(OR(A33="",C33=""),"",A33&"|"&C33) | AB33: =IF(OR(AA33="",Q33=""),"",IF(COUNTIF(기준SD!$E$2:$E$500,AA33)=0,"",IF(COUNTIFS(기준SD!$E$2:$E$500,AA33,기준SD!$C$2:$C$500,"<="&Q33)=0,_xlfn.MINIFS(기준SD!$C$2:$C$500,기준SD!$E$2:$E$500,AA33),_xlfn.MAXIFS(기준SD!$C$2:$C$500,기준SD!$E$2:$E$500,AA33,기준SD!$C$2:$C$500,"<="&Q33)))) | AC33: =IF(AB33="","",IF(COUNTIFS(기준SD!$E$2:$E$500,AA33,기준SD!$C$2:$C$500,">="&Q33)=0,_xlfn.MAXIFS(기준SD!$C$2:$C$500,기준SD!$E$2:$E$500,AA33),_xlfn.MINIFS(기준SD!$C$2:$C$500,기준SD!$E$2:$E$500,AA33,기준SD!$C$2:$C$500,">="&Q33))) | AD33: =IF(AB33="","",SUMIFS(기준SD!$D$2:$D$500,기준SD!$E$2:$E$500,AA33,기준SD!$C$2:$C$500,AB33)) | AE33: =IF(AC33="","",SUMIFS(기준SD!$D$2:$D$500,기준SD!$E$2:$E$500,AA33,기준SD!$C$2:$C$500,AC33))
P34: =COUNT(F34:O34) -> 0 | Q34: =IF(P34<2,"",AVERAGE(F34:O34)) | R34: =IF(P34<2,"",STDEV(F34:O34)) | S34: =IF(P34<2,"",IF(Q34=0,"",R34/Q34*100)) | T34: =IF(AB34="","",IF(AB34=AC34,AD34,AD34+(AE34-AD34)*(Q34-AB34)/(AC34-AB34))) | U34: =IF(OR(T34="",R34=""),"",IF(T34=0,"",R34/T34)) | V34: =IF(Q34="","",IF(T34="","기준없음",IF(R34<=T34*$C$2,"합격","불합격"))) | W34: =IF(OR(Q34="",D34=""),"",Q34-D34) | X34: =IF(W34="","",IF(E34<>"",E34,IF(T34="","",T34*$C$3))) | Y34: =IF(OR(W34="",X34=""),"",IF(ABS(W34)<=X34,"합격","불합격")) | Z34: =IF(OR(AA34="",Q34=""),"",IF(AB34="","기준SD 데이터 없음 ",IF(Q34<_xlfn.MINIFS(기준SD!$C$2:$C$500,기준SD!$E$2:$E$500,AA34),"최저 레벨 미만→최저 레벨 SD 적용 ",IF(Q34>_xlfn.MAXIFS(기준SD!$C$2:$C$500,기준SD!$E$2:$E$500,AA34),"최고 레벨 초과→최고 레벨 SD 적용 ","")))&IF(SUMIFS(원소정보!$E$2:$E$200,원소정보!$F$2:$F$200,AA34)>0,IF(Q34>SUMIFS(원소정보!$E$2:$E$200,원소정보!$F$2:$F$200,AA34),"검량범위 초과 ",""),"")&IF(SUMIFS(원소정보!$D$2:$D$200,원소정보!$F$2:$F$200,AA34)>0,IF(Q34<SUMIFS(원소정보!$D$2:$D$200,원소정보!$F$2:$F$200,AA34)/10000,"검출한계 미만",""),"")) | AA34: =IF(OR(A34="",C34=""),"",A34&"|"&C34) | AB34: =IF(OR(AA34="",Q34=""),"",IF(COUNTIF(기준SD!$E$2:$E$500,AA34)=0,"",IF(COUNTIFS(기준SD!$E$2:$E$500,AA34,기준SD!$C$2:$C$500,"<="&Q34)=0,_xlfn.MINIFS(기준SD!$C$2:$C$500,기준SD!$E$2:$E$500,AA34),_xlfn.MAXIFS(기준SD!$C$2:$C$500,기준SD!$E$2:$E$500,AA34,기준SD!$C$2:$C$500,"<="&Q34)))) | AC34: =IF(AB34="","",IF(COUNTIFS(기준SD!$E$2:$E$500,AA34,기준SD!$C$2:$C$500,">="&Q34)=0,_xlfn.MAXIFS(기준SD!$C$2:$C$500,기준SD!$E$2:$E$500,AA34),_xlfn.MINIFS(기준SD!$C$2:$C$500,기준SD!$E$2:$E$500,AA34,기준SD!$C$2:$C$500,">="&Q34))) | AD34: =IF(AB34="","",SUMIFS(기준SD!$D$2:$D$500,기준SD!$E$2:$E$500,AA34,기준SD!$C$2:$C$500,AB34)) | AE34: =IF(AC34="","",SUMIFS(기준SD!$D$2:$D$500,기준SD!$E$2:$E$500,AA34,기준SD!$C$2:$C$500,AC34))
P35: =COUNT(F35:O35) -> 0 | Q35: =IF(P35<2,"",AVERAGE(F35:O35)) | R35: =IF(P35<2,"",STDEV(F35:O35)) | S35: =IF(P35<2,"",IF(Q35=0,"",R35/Q35*100)) | T35: =IF(AB35="","",IF(AB35=AC35,AD35,AD35+(AE35-AD35)*(Q35-AB35)/(AC35-AB35))) | U35: =IF(OR(T35="",R35=""),"",IF(T35=0,"",R35/T35)) | V35: =IF(Q35="","",IF(T35="","기준없음",IF(R35<=T35*$C$2,"합격","불합격"))) | W35: =IF(OR(Q35="",D35=""),"",Q35-D35) | X35: =IF(W35="","",IF(E35<>"",E35,IF(T35="","",T35*$C$3))) | Y35: =IF(OR(W35="",X35=""),"",IF(ABS(W35)<=X35,"합격","불합격")) | Z35: =IF(OR(AA35="",Q35=""),"",IF(AB35="","기준SD 데이터 없음 ",IF(Q35<_xlfn.MINIFS(기준SD!$C$2:$C$500,기준SD!$E$2:$E$500,AA35),"최저 레벨 미만→최저 레벨 SD 적용 ",IF(Q35>_xlfn.MAXIFS(기준SD!$C$2:$C$500,기준SD!$E$2:$E$500,AA35),"최고 레벨 초과→최고 레벨 SD 적용 ","")))&IF(SUMIFS(원소정보!$E$2:$E$200,원소정보!$F$2:$F$200,AA35)>0,IF(Q35>SUMIFS(원소정보!$E$2:$E$200,원소정보!$F$2:$F$200,AA35),"검량범위 초과 ",""),"")&IF(SUMIFS(원소정보!$D$2:$D$200,원소정보!$F$2:$F$200,AA35)>0,IF(Q35<SUMIFS(원소정보!$D$2:$D$200,원소정보!$F$2:$F$200,AA35)/10000,"검출한계 미만",""),"")) | AA35: =IF(OR(A35="",C35=""),"",A35&"|"&C35) | AB35: =IF(OR(AA35="",Q35=""),"",IF(COUNTIF(기준SD!$E$2:$E$500,AA35)=0,"",IF(COUNTIFS(기준SD!$E$2:$E$500,AA35,기준SD!$C$2:$C$500,"<="&Q35)=0,_xlfn.MINIFS(기준SD!$C$2:$C$500,기준SD!$E$2:$E$500,AA35),_xlfn.MAXIFS(기준SD!$C$2:$C$500,기준SD!$E$2:$E$500,AA35,기준SD!$C$2:$C$500,"<="&Q35)))) | AC35: =IF(AB35="","",IF(COUNTIFS(기준SD!$E$2:$E$500,AA35,기준SD!$C$2:$C$500,">="&Q35)=0,_xlfn.MAXIFS(기준SD!$C$2:$C$500,기준SD!$E$2:$E$500,AA35),_xlfn.MINIFS(기준SD!$C$2:$C$500,기준SD!$E$2:$E$500,AA35,기준SD!$C$2:$C$500,">="&Q35))) | AD35: =IF(AB35="","",SUMIFS(기준SD!$D$2:$D$500,기준SD!$E$2:$E$500,AA35,기준SD!$C$2:$C$500,AB35)) | AE35: =IF(AC35="","",SUMIFS(기준SD!$D$2:$D$500,기준SD!$E$2:$E$500,AA35,기준SD!$C$2:$C$500,AC35))
P36: =COUNT(F36:O36) -> 0 | Q36: =IF(P36<2,"",AVERAGE(F36:O36)) | R36: =IF(P36<2,"",STDEV(F36:O36)) | S36: =IF(P36<2,"",IF(Q36=0,"",R36/Q36*100)) | T36: =IF(AB36="","",IF(AB36=AC36,AD36,AD36+(AE36-AD36)*(Q36-AB36)/(AC36-AB36))) | U36: =IF(OR(T36="",R36=""),"",IF(T36=0,"",R36/T36)) | V36: =IF(Q36="","",IF(T36="","기준없음",IF(R36<=T36*$C$2,"합격","불합격"))) | W36: =IF(OR(Q36="",D36=""),"",Q36-D36) | X36: =IF(W36="","",IF(E36<>"",E36,IF(T36="","",T36*$C$3))) | Y36: =IF(OR(W36="",X36=""),"",IF(ABS(W36)<=X36,"합격","불합격")) | Z36: =IF(OR(AA36="",Q36=""),"",IF(AB36="","기준SD 데이터 없음 ",IF(Q36<_xlfn.MINIFS(기준SD!$C$2:$C$500,기준SD!$E$2:$E$500,AA36),"최저 레벨 미만→최저 레벨 SD 적용 ",IF(Q36>_xlfn.MAXIFS(기준SD!$C$2:$C$500,기준SD!$E$2:$E$500,AA36),"최고 레벨 초과→최고 레벨 SD 적용 ","")))&IF(SUMIFS(원소정보!$E$2:$E$200,원소정보!$F$2:$F$200,AA36)>0,IF(Q36>SUMIFS(원소정보!$E$2:$E$200,원소정보!$F$2:$F$200,AA36),"검량범위 초과 ",""),"")&IF(SUMIFS(원소정보!$D$2:$D$200,원소정보!$F$2:$F$200,AA36)>0,IF(Q36<SUMIFS(원소정보!$D$2:$D$200,원소정보!$F$2:$F$200,AA36)/10000,"검출한계 미만",""),"")) | AA36: =IF(OR(A36="",C36=""),"",A36&"|"&C36) | AB36: =IF(OR(AA36="",Q36=""),"",IF(COUNTIF(기준SD!$E$2:$E$500,AA36)=0,"",IF(COUNTIFS(기준SD!$E$2:$E$500,AA36,기준SD!$C$2:$C$500,"<="&Q36)=0,_xlfn.MINIFS(기준SD!$C$2:$C$500,기준SD!$E$2:$E$500,AA36),_xlfn.MAXIFS(기준SD!$C$2:$C$500,기준SD!$E$2:$E$500,AA36,기준SD!$C$2:$C$500,"<="&Q36)))) | AC36: =IF(AB36="","",IF(COUNTIFS(기준SD!$E$2:$E$500,AA36,기준SD!$C$2:$C$500,">="&Q36)=0,_xlfn.MAXIFS(기준SD!$C$2:$C$500,기준SD!$E$2:$E$500,AA36),_xlfn.MINIFS(기준SD!$C$2:$C$500,기준SD!$E$2:$E$500,AA36,기준SD!$C$2:$C$500,">="&Q36))) | AD36: =IF(AB36="","",SUMIFS(기준SD!$D$2:$D$500,기준SD!$E$2:$E$500,AA36,기준SD!$C$2:$C$500,AB36)) | AE36: =IF(AC36="","",SUMIFS(기준SD!$D$2:$D$500,기준SD!$E$2:$E$500,AA36,기준SD!$C$2:$C$500,AC36))
... P80: =COUNT(F80:O80) -> 0 | Q80: =IF(P80<2,"",AVERAGE(F80:O80)) | R80: =IF(P80<2,"",STDEV(F80:O80)) | S80: =IF(P80<2,"",IF(Q80=0,"",R80/Q80*100)) | T80: =IF(AB80="","",IF(AB80=AC80,AD80,AD80+(AE80-AD80)*(Q80-AB80)/(AC80-AB80))) | U80: =IF(OR(T80="",R80=""),"",IF(T80=0,"",R80/T80)) | V80: =IF(Q80="","",IF(T80="","기준없음",IF(R80<=T80*$C$2,"합격","불합격"))) | W80: =IF(OR(Q80="",D80=""),"",Q80-D80) | X80: =IF(W80="","",IF(E80<>"",E80,IF(T80="","",T80*$C$3))) | Y80: =IF(OR(W80="",X80=""),"",IF(ABS(W80)<=X80,"합격","불합격")) | Z80: =IF(OR(AA80="",Q80=""),"",IF(AB80="","기준SD 데이터 없음 ",IF(Q80<_xlfn.MINIFS(기준SD!$C$2:$C$500,기준SD!$E$2:$E$500,AA80),"최저 레벨 미만→최저 레벨 SD 적용 ",IF(Q80>_xlfn.MAXIFS(기준SD!$C$2:$C$500,기준SD!$E$2:$E$500,AA80),"최고 레벨 초과→최고 레벨 SD 적용 ","")))&IF(SUMIFS(원소정보!$E$2:$E$200,원소정보!$F$2:$F$200,AA80)>0,IF(Q80>SUMIFS(원소정보!$E$2:$E$200,원소정보!$F$2:$F$200,AA80),"검량범위 초과 ",""),"")&IF(SUMIFS(원소정보!$D$2:$D$200,원소정보!$F$2:$F$200,AA80)>0,IF(Q80<SUMIFS(원소정보!$D$2:$D$200,원소정보!$F$2:$F$200,AA80)/10000,"검출한계 미만",""),"")) | AA80: =IF(OR(A80="",C80=""),"",A80&"|"&C80) | AB80: =IF(OR(AA80="",Q80=""),"",IF(COUNTIF(기준SD!$E$2:$E$500,AA80)=0,"",IF(COUNTIFS(기준SD!$E$2:$E$500,AA80,기준SD!$C$2:$C$500,"<="&Q80)=0,_xlfn.MINIFS(기준SD!$C$2:$C$500,기준SD!$E$2:$E$500,AA80),_xlfn.MAXIFS(기준SD!$C$2:$C$500,기준SD!$E$2:$E$500,AA80,기준SD!$C$2:$C$500,"<="&Q80)))) | AC80: =IF(AB80="","",IF(COUNTIFS(기준SD!$E$2:$E$500,AA80,기준SD!$C$2:$C$500,">="&Q80)=0,_xlfn.MAXIFS(기준SD!$C$2:$C$500,기준SD!$E$2:$E$500,AA80),_xlfn.MINIFS(기준SD!$C$2:$C$500,기준SD!$E$2:$E$500,AA80,기준SD!$C$2:$C$500,">="&Q80))) | AD80: =IF(AB80="","",SUMIFS(기준SD!$D$2:$D$500,기준SD!$E$2:$E$500,AA80,기준SD!$C$2:$C$500,AB80)) | AE80: =IF(AC80="","",SUMIFS(기준SD!$D$2:$D$500,기준SD!$E$2:$E$500,AA80,기준SD!$C$2:$C$500,AC80))

Sheet 기준SD
A1: 베이스 | B1: 원소 | C1: 농도레벨(%) | D1: 정밀도 1×SD(%) | E1: 키(자동) | F1: 비고
A2: Fe | B2: Al | C2: 0.005 | D2: 0.001 | E2: =IF(OR(A2="",B2=""),"",A2&"|"&B2) -> Fe|Al | F2: 출처: SPECTRO Application Report, 6. Typical Detection Limits and Precision Fe-Base (제조사 제공)
A3: Fe | B3: Al | C3: 0.01 | D3: 0.001 | E3: =IF(OR(A3="",B3=""),"",A3&"|"&B3) -> Fe|Al
A4: Fe | B4: Al | C4: 0.05 | D4: 0.001 | E4: =IF(OR(A4="",B4=""),"",A4&"|"&B4) -> Fe|Al
A5: Fe | B5: Al | C5: 0.1 | D5: 0.002 | E5: =IF(OR(A5="",B5=""),"",A5&"|"&B5) -> Fe|Al
A6: Fe | B6: Al | C6: 0.3 | D6: 0.004 | E6: =IF(OR(A6="",B6=""),"",A6&"|"&B6) -> Fe|Al
A7: Fe | B7: Al | C7: 0.5 | D7: 0.005 | E7: =IF(OR(A7="",B7=""),"",A7&"|"&B7) -> Fe|Al
A8: Fe | B8: As | C8: 0.01 | D8: 0.002 | E8: =IF(OR(A8="",B8=""),"",A8&"|"&B8) -> Fe|As
A9: Fe | B9: As | C9: 0.05 | D9: 0.002 | E9: =IF(OR(A9="",B9=""),"",A9&"|"&B9) -> Fe|As
A10: Fe | B10: As | C10: 0.1 | D10: 0.004 | E10: =IF(OR(A10="",B10=""),"",A10&"|"&B10) -> Fe|As
A11: Fe | B11: B | C11: 0.005 | D11: 0.0002 | E11: =IF(OR(A11="",B11=""),"",A11&"|"&B11) -> Fe|B
A12: Fe | B12: B | C12: 0.01 | D12: 0.0004 | E12: =IF(OR(A12="",B12=""),"",A12&"|"&B12) -> Fe|B
A13: Fe | B13: C | C13: 0.01 | D13: 0.001 | E13: =IF(OR(A13="",B13=""),"",A13&"|"&B13) -> Fe|C
A14: Fe | B14: C | C14: 0.05 | D14: 0.002 | E14: =IF(OR(A14="",B14=""),"",A14&"|"&B14) -> Fe|C
... A49: Fe | B49: Cu | C49: 0.1 | D49: 0.002 | E49: =IF(OR(A49="",B49=""),"",A49&"|"&B49) -> Fe|Cu
A50: Fe | B50: Cu | C50: 0.3 | D50: 0.001 | E50: =IF(OR(A50="",B50=""),"",A50&"|"&B50) -> Fe|Cu | F50: 원본 표 값 그대로 입력(0.100% 레벨보다 작음) - 제조사 확인 권장
A51: Fe | B51: Cu | C51: 0.5 | D51: 0.004 | E51: =IF(OR(A51="",B51=""),"",A51&"|"&B51) -> Fe|Cu
A52: Fe | B52: Cu | C52: 1 | D52: 0.01 | E52: =IF(OR(A52="",B52=""),"",A52&"|"&B52) -> Fe|Cu
A53: Fe | B53: Cu | C53: 2 | D53: 0.012 | E53: =IF(OR(A53="",B53=""),"",A53&"|"&B53) -> Fe|Cu
A54: Fe | B54: Cu | C54: 5 | D54: 0.018 | E54: =IF(OR(A54="",B54=""),"",A54&"|"&B54) -> Fe|Cu
A55: Fe | B55: Mg | C55: 0.005 | D55: 0.001 | E55: =IF(OR(A55="",B55=""),"",A55&"|"&B55) -> Fe|Mg
A56: Fe | B56: Mg | C56: 0.01 | D56: 0.001 | E56: =IF(OR(A56="",B56=""),"",A56&"|"&B56) -> Fe|Mg
A57: Fe | B57: Mg | C57: 0.05 | D57: 0.005 | E57: =IF(OR(A57="",B57=""),"",A57&"|"&B57) -> Fe|Mg
A58: Fe | B58: Mg | C58: 0.1 | D58: 0.008 | E58: =IF(OR(A58="",B58=""),"",A58&"|"&B58) -> Fe|Mg
A59: Fe | B59: Mn | C59: 0.005 | D59: 0.001 | E59: =IF(OR(A59="",B59=""),"",A59&"|"&B59) -> Fe|Mn
A60: Fe | B60: Mn | C60: 0.01 | D60: 0.001 | E60: =IF(OR(A60="",B60=""),"",A60&"|"&B60) -> Fe|Mn
A61: Fe | B61: Mn | C61: 0.05 | D61: 0.001 | E61: =IF(OR(A61="",B61=""),"",A61&"|"&B61) -> Fe|Mn
A62: Fe | B62: Mn | C62: 0.1 | D62: 0.001 | E62: =IF(OR(A62="",B62=""),"",A62&"|"&B62) -> Fe|Mn
... A119: Fe | B119: Sn | C119: 0.05 | D119: 0.001 | E119: =IF(OR(A119="",B119=""),"",A119&"|"&B119) -> Fe|Sn
E120: =IF(OR(A120="",B120=""),"",A120&"|"&B120)
E121: =IF(OR(A121="",B121=""),"",A121&"|"&B121)
E122: =IF(OR(A122="",B122=""),"",A122&"|"&B122)
E123: =IF(OR(A123="",B123=""),"",A123&"|"&B123)
E124: =IF(OR(A124="",B124=""),"",A124&"|"&B124)
E125: =IF(OR(A125="",B125=""),"",A125&"|"&B125)
E126: =IF(OR(A126="",B126=""),"",A126&"|"&B126)
E127: =IF(OR(A127="",B127=""),"",A127&"|"&B127)
E128: =IF(OR(A128="",B128=""),"",A128&"|"&B128)
E129: =IF(OR(A129="",B129=""),"",A129&"|"&B129)
E130: =IF(OR(A130="",B130=""),"",A130&"|"&B130)
...

Sheet 원소정보
A1: 베이스 | B1: 원소 | C1: UV Probe | D1: 검출한계(ppm) | E1: 검량범위 상한(%) | F1: 키(자동)
A2: Fe | B2: Al | D2: 30 | E2: 6.24 | F2: =IF(OR(A2="",B2=""),"",A2&"|"&B2) -> Fe|Al
A3: Fe | B3: As | C3: O | D3: 50 | E3: 0.28 | F3: =IF(OR(A3="",B3=""),"",A3&"|"&B3) -> Fe|As
A4: Fe | B4: B | C4: O | D4: 5 | E4: 0.13 | F4: =IF(OR(A4="",B4=""),"",A4&"|"&B4) -> Fe|B
A5: Fe | B5: C | C5: O | D5: 60 | E5: 5.4 | F5: =IF(OR(A5="",B5=""),"",A5&"|"&B5) -> Fe|C
A6: Fe | B6: C(air) | D6: 100 | E6: 5.4 | F6: =IF(OR(A6="",B6=""),"",A6&"|"&B6) -> Fe|C(air)
A7: Fe | B7: Co | D7: 90 | E7: 21.6 | F7: =IF(OR(A7="",B7=""),"",A7&"|"&B7) -> Fe|Co
A8: Fe | B8: Cr | D8: 60 | E8: 39.6 | F8: =IF(OR(A8="",B8=""),"",A8&"|"&B8) -> Fe|Cr
A9: Fe | B9: Cu | D9: 20 | E9: 9.72 | F9: =IF(OR(A9="",B9=""),"",A9&"|"&B9) -> Fe|Cu
A10: Fe | B10: Mg | D10: 20 | E10: 0.28 | F10: =IF(OR(A10="",B10=""),"",A10&"|"&B10) -> Fe|Mg
A11: Fe | B11: Mn | D11: 40 | E11: 24 | F11: =IF(OR(A11="",B11=""),"",A11&"|"&B11) -> Fe|Mn
A12: Fe | B12: Mo | D12: 30 | E12: 11.4 | F12: =IF(OR(A12="",B12=""),"",A12&"|"&B12) -> Fe|Mo
A13: Fe | B13: Nb | D13: 50 | E13: 3.6 | F13: =IF(OR(A13="",B13=""),"",A13&"|"&B13) -> Fe|Nb
A14: Fe | B14: Ni | D14: 80 | E14: 55.2 | F14: =IF(OR(A14="",B14=""),"",A14&"|"&B14) -> Fe|Ni
A15: Fe | B15: P | C15: O | D15: 30 | E15: 2.88 | F15: =IF(OR(A15="",B15=""),"",A15&"|"&B15) -> Fe|P
A16: Fe | B16: Pb | D16: 100 | E16: 0.32 | F16: =IF(OR(A16="",B16=""),"",A16&"|"&B16) -> Fe|Pb
A17: Fe | B17: S | C17: O | D17: 20 | E17: 0.51 | F17: =IF(OR(A17="",B17=""),"",A17&"|"&B17) -> Fe|S
A18: Fe | B18: Si | D18: 70 | E18: 24 | F18: =IF(OR(A18="",B18=""),"",A18&"|"&B18) -> Fe|Si
A19: Fe | B19: Sn | C19: O | D19: 20 | E19: 0.3 | F19: =IF(OR(A19="",B19=""),"",A19&"|"&B19) -> Fe|Sn
F20: =IF(OR(A20="",B20=""),"",A20&"|"&B20)
F21: =IF(OR(A21="",B21=""),"",A21&"|"&B21)
F22: =IF(OR(A22="",B22=""),"",A22&"|"&B22)
F23: =IF(OR(A23="",B23=""),"",A23&"|"&B23)
F24: =IF(OR(A24="",B24=""),"",A24&"|"&B24)
F25: =IF(OR(A25="",B25=""),"",A25&"|"&B25)
F26: =IF(OR(A26="",B26=""),"",A26&"|"&B26)
F27: =IF(OR(A27="",B27=""),"",A27&"|"&B27)
F28: =IF(OR(A28="",B28=""),"",A28&"|"&B28)
F29: =IF(OR(A29="",B29=""),"",A29&"|"&B29)
F30: =IF(OR(A30="",B30=""),"",A30&"|"&B30)
F31: =IF(OR(A31="",B31=""),"",A31&"|"&B31)
... F200: =IF(OR(A200="",B200=""),"",A200&"|"&B200)

Sheet 기준표_확인
A1: 베이스 선택 | B1: Fe | C1: ← Fe/Cu/Al 선택 후, 3행 원소명을 해당 표에 맞게 수정
A3: 원소 | B3: Al | C3: As | D3: B | E3: C | F3: C(air) | G3: Co | H3: Cr | I3: Cu | J3: Mg | K3: Mn | L3: Mo | M3: Nb | N3: Ni | O3: P | P3: Pb | Q3: S | R3: Si | S3: Sn
A4: UV Probe | B4: =IF(COUNTIF(원소정보!$F$2:$F$200,$B$1&"|"&B$3)=0,"",IF(INDEX(원소정보!$C$2:$C$200,MATCH($B$1&"|"&B$3,원소정보!$F$2:$F$200,0))="","","x")) | C4: =IF(COUNTIF(원소정보!$F$2:$F$200,$B$1&"|"&C$3)=0,"",IF(INDEX(원소정보!$C$2:$C$200,MATCH($B$1&"|"&C$3,원소정보!$F$2:$F$200,0))="","","x")) -> x | D4: =IF(COUNTIF(원소정보!$F$2:$F$200,$B$1&"|"&D$3)=0,"",IF(INDEX(원소정보!$C$2:$C$200,MATCH($B$1&"|"&D$3,원소정보!$F$2:$F$200,0))="","","x")) -> x | E4: =IF(COUNTIF(원소정보!$F$2:$F$200,$B$1&"|"&E$3)=0,"",IF(INDEX(원소정보!$C$2:$C$200,MATCH($B$1&"|"&E$3,원소정보!$F$2:$F$200,0))="","","x")) -> x | F4: =IF(COUNTIF(원소정보!$F$2:$F$200,$B$1&"|"&F$3)=0,"",IF(INDEX(원소정보!$C$2:$C$200,MATCH($B$1&"|"&F$3,원소정보!$F$2:$F$200,0))="","","x")) | G4: =IF(COUNTIF(원소정보!$F$2:$F$200,$B$1&"|"&G$3)=0,"",IF(INDEX(원소정보!$C$2:$C$200,MATCH($B$1&"|"&G$3,원소정보!$F$2:$F$200,0))="","","x")) | H4: =IF(COUNTIF(원소정보!$F$2:$F$200,$B$1&"|"&H$3)=0,"",IF(INDEX(원소정보!$C$2:$C$200,MATCH($B$1&"|"&H$3,원소정보!$F$2:$F$200,0))="","","x")) | I4: =IF(COUNTIF(원소정보!$F$2:$F$200,$B$1&"|"&I$3)=0,"",IF(INDEX(원소정보!$C$2:$C$200,MATCH($B$1&"|"&I$3,원소정보!$F$2:$F$200,0))="","","x")) | ... S4: =IF(COUNTIF(원소정보!$F$2:$F$200,$B$1&"|"&S$3)=0,"",IF(INDEX(원소정보!$C$2:$C$200,MATCH($B$1&"|"&S$3,원소정보!$F$2:$F$200,0))="","","x")) -> x
A5: 검출한계(ppm) | B5: =IF(COUNTIF(원소정보!$F$2:$F$200,$B$1&"|"&B$3)=0,"",INDEX(원소정보!$D$2:$D$200,MATCH($B$1&"|"&B$3,원소정보!$F$2:$F$200,0))) -> 30 | C5: =IF(COUNTIF(원소정보!$F$2:$F$200,$B$1&"|"&C$3)=0,"",INDEX(원소정보!$D$2:$D$200,MATCH($B$1&"|"&C$3,원소정보!$F$2:$F$200,0))) -> 50 | D5: =IF(COUNTIF(원소정보!$F$2:$F$200,$B$1&"|"&D$3)=0,"",INDEX(원소정보!$D$2:$D$200,MATCH($B$1&"|"&D$3,원소정보!$F$2:$F$200,0))) -> 5 | E5: =IF(COUNTIF(원소정보!$F$2:$F$200,$B$1&"|"&E$3)=0,"",INDEX(원소정보!$D$2:$D$200,MATCH($B$1&"|"&E$3,원소정보!$F$2:$F$200,0))) -> 60 | F5: =IF(COUNTIF(원소정보!$F$2:$F$200,$B$1&"|"&F$3)=0,"",INDEX(원소정보!$D$2:$D$200,MATCH($B$1&"|"&F$3,원소정보!$F$2:$F$200,0))) -> 100 | G5: =IF(COUNTIF(원소정보!$F$2:$F$200,$B$1&"|"&G$3)=0,"",INDEX(원소정보!$D$2:$D$200,MATCH($B$1&"|"&G$3,원소정보!$F$2:$F$200,0))) -> 90 | H5: =IF(COUNTIF(원소정보!$F$2:$F$200,$B$1&"|"&H$3)=0,"",INDEX(원소정보!$D$2:$D$200,MATCH($B$1&"|"&H$3,원소정보!$F$2:$F$200,0))) -> 60 | I5: =IF(COUNTIF(원소정보!$F$2:$F$200,$B$1&"|"&I$3)=0,"",INDEX(원소정보!$D$2:$D$200,MATCH($B$1&"|"&I$3,원소정보!$F$2:$F$200,0))) -> 20 | ... S5: =IF(COUNTIF(원소정보!$F$2:$F$200,$B$1&"|"&S$3)=0,"",INDEX(원소정보!$D$2:$D$200,MATCH($B$1&"|"&S$3,원소정보!$F$2:$F$200,0))) -> 20
A6: 검량범위(%) | B6: =IF(COUNTIF(원소정보!$F$2:$F$200,$B$1&"|"&B$3)=0,"",INDEX(원소정보!$E$2:$E$200,MATCH($B$1&"|"&B$3,원소정보!$F$2:$F$200,0))) -> 6.24 | C6: =IF(COUNTIF(원소정보!$F$2:$F$200,$B$1&"|"&C$3)=0,"",INDEX(원소정보!$E$2:$E$200,MATCH($B$1&"|"&C$3,원소정보!$F$2:$F$200,0))) -> 0.28 | D6: =IF(COUNTIF(원소정보!$F$2:$F$200,$B$1&"|"&D$3)=0,"",INDEX(원소정보!$E$2:$E$200,MATCH($B$1&"|"&D$3,원소정보!$F$2:$F$200,0))) -> 0.13 | E6: =IF(COUNTIF(원소정보!$F$2:$F$200,$B$1&"|"&E$3)=0,"",INDEX(원소정보!$E$2:$E$200,MATCH($B$1&"|"&E$3,원소정보!$F$2:$F$200,0))) -> 5.4 | F6: =IF(COUNTIF(원소정보!$F$2:$F$200,$B$1&"|"&F$3)=0,"",INDEX(원소정보!$E$2:$E$200,MATCH($B$1&"|"&F$3,원소정보!$F$2:$F$200,0))) -> 5.4 | G6: =IF(COUNTIF(원소정보!$F$2:$F$200,$B$1&"|"&G$3)=0,"",INDEX(원소정보!$E$2:$E$200,MATCH($B$1&"|"&G$3,원소정보!$F$2:$F$200,0))) -> 21.6 | H6: =IF(COUNTIF(원소정보!$F$2:$F$200,$B$1&"|"&H$3)=0,"",INDEX(원소정보!$E$2:$E$200,MATCH($B$1&"|"&H$3,원소정보!$F$2:$F$200,0))) -> 39.6 | I6: =IF(COUNTIF(원소정보!$F$2:$F$200,$B$1&"|"&I$3)=0,"",INDEX(원소정보!$E$2:$E$200,MATCH($B$1&"|"&I$3,원소정보!$F$2:$F$200,0))) -> 9.72 | ... S6: =IF(COUNTIF(원소정보!$F$2:$F$200,$B$1&"|"&S$3)=0,"",INDEX(원소정보!$E$2:$E$200,MATCH($B$1&"|"&S$3,원소정보!$F$2:$F$200,0))) -> 0.3
A7: Conc. level(%) / 1×SD(%)
A8: 0.005 | B8: =IF(COUNTIFS(기준SD!$E$2:$E$500,$B$1&"|"&B$3,기준SD!$C$2:$C$500,$A8)=0,"",SUMIFS(기준SD!$D$2:$D$500,기준SD!$E$2:$E$500,$B$1&"|"&B$3,기준SD!$C$2:$C$500,$A8)) -> 0.001 | C8: =IF(COUNTIFS(기준SD!$E$2:$E$500,$B$1&"|"&C$3,기준SD!$C$2:$C$500,$A8)=0,"",SUMIFS(기준SD!$D$2:$D$500,기준SD!$E$2:$E$500,$B$1&"|"&C$3,기준SD!$C$2:$C$500,$A8)) | D8: =IF(COUNTIFS(기준SD!$E$2:$E$500,$B$1&"|"&D$3,기준SD!$C$2:$C$500,$A8)=0,"",SUMIFS(기준SD!$D$2:$D$500,기준SD!$E$2:$E$500,$B$1&"|"&D$3,기준SD!$C$2:$C$500,$A8)) -> 0.0002 | E8: =IF(COUNTIFS(기준SD!$E$2:$E$500,$B$1&"|"&E$3,기준SD!$C$2:$C$500,$A8)=0,"",SUMIFS(기준SD!$D$2:$D$500,기준SD!$E$2:$E$500,$B$1&"|"&E$3,기준SD!$C$2:$C$500,$A8)) | F8: =IF(COUNTIFS(기준SD!$E$2:$E$500,$B$1&"|"&F$3,기준SD!$C$2:$C$500,$A8)=0,"",SUMIFS(기준SD!$D$2:$D$500,기준SD!$E$2:$E$500,$B$1&"|"&F$3,기준SD!$C$2:$C$500,$A8)) | G8: =IF(COUNTIFS(기준SD!$E$2:$E$500,$B$1&"|"&G$3,기준SD!$C$2:$C$500,$A8)=0,"",SUMIFS(기준SD!$D$2:$D$500,기준SD!$E$2:$E$500,$B$1&"|"&G$3,기준SD!$C$2:$C$500,$A8)) | H8: =IF(COUNTIFS(기준SD!$E$2:$E$500,$B$1&"|"&H$3,기준SD!$C$2:$C$500,$A8)=0,"",SUMIFS(기준SD!$D$2:$D$500,기준SD!$E$2:$E$500,$B$1&"|"&H$3,기준SD!$C$2:$C$500,$A8)) | I8: =IF(COUNTIFS(기준SD!$E$2:$E$500,$B$1&"|"&I$3,기준SD!$C$2:$C$500,$A8)=0,"",SUMIFS(기준SD!$D$2:$D$500,기준SD!$E$2:$E$500,$B$1&"|"&I$3,기준SD!$C$2:$C$500,$A8)) -> 0.0003 | ... S8: =IF(COUNTIFS(기준SD!$E$2:$E$500,$B$1&"|"&S$3,기준SD!$C$2:$C$500,$A8)=0,"",SUMIFS(기준SD!$D$2:$D$500,기준SD!$E$2:$E$500,$B$1&"|"&S$3,기준SD!$C$2:$C$500,$A8)) -> 0.001
